Workbook

Sheet DEMONSTRATIVO
A1: DRE - DEMONSTRATIVO DE RESULTADO
B2: 45658 | C2: 45689 | D2: 45717 | E2: 45748 | F2: 45778 | G2: 45809 | H2: 45839 | I2: 45870 | J2: 45901 | K2: 45931 | L2: 45962 | M2: 45992 | N2: Acumulado
A3: TOTAL - RECEITA BRUTA | B3: =B7 -> 0 | C3: =C7 -> 0 | D3: =D7 -> 0 | E3: =E7 -> 0 | F3: =F7 -> 0 | G3: =G7 -> 0 | H3: =H7 -> 0 | I3: =I7 -> 0 | ... M3: =M7 -> 0 | N3: =SUM(B3:M3) -> 0
A4: TAXA CARTÃO DE CRÉDITO
A5: CARTÕES E PLANOS | B5: ='DRE RECEITAS'!C2 -> 0 | C5: ='DRE RECEITAS'!C3 -> 0 | D5: ='DRE RECEITAS'!C4 -> 0 | E5: ='DRE RECEITAS'!C5 -> 0 | F5: ='DRE RECEITAS'!C6 -> 0 | G5: ='DRE RECEITAS'!C7 -> 0 | H5: ='DRE RECEITAS'!C8 -> 0 | I5: ='DRE RECEITAS'!C9 -> 0 | J5: ='DRE RECEITAS'!C10 -> 0 | K5: ='DRE RECEITAS'!C11 -> 0 | L5: ='DRE RECEITAS'!C12 -> 0 | M5: ='DRE RECEITAS'!C13 -> 0 | N5: =SUM(B5:M5) -> 0
A6: DINHEIRO&PIX | B6: ='DRE RECEITAS'!B2 -> 0 | C6: ='DRE RECEITAS'!B3 -> 0 | N6: =SUM(B6:M6) -> 0
A7: TOTAL - FATURAMENTO LIQUIDO | B7: =SUM(B5:B6) -> 0 | C7: =SUM(C5:C6) -> 0 | D7: =SUM(D5:D6) -> 0 | E7: =SUM(E5:E6) -> 0 | F7: =SUM(F5:F6) -> 0 | G7: =SUM(G5:G6) -> 0 | H7: =SUM(H5:H6) -> 0 | I7: =SUM(I5:I6) -> 0 | ... N7: =SUM(N5:N6) -> 0
A8: % Sobre Faturamento Bruto | B8: =B7/B3*100 -> #DIV/0! | C8: =C7/C3*100 -> #DIV/0! | D8: =D7/D3*100 -> #DIV/0! | E8: =E7/E3*100 -> #DIV/0! | F8: =F7/F3*100 -> #DIV/0! | G8: =G7/G3*100 -> #DIV/0! | H8: =H7/H3*100 -> #DIV/0! | I8: =I7/I3*100 -> #DIV/0! | ... N8: =N7/N3*100 -> #DIV/0!
A9: CUSTO ALIMENTAR
A10: GENEROS ALIMENTICIOS | B10: ='DRE DESPESAS'!A2 -> 0 | C10: ='DRE DESPESAS'!A3 -> 0 | N10: =SUM(B10:M10) -> 0
A11: GENEROS DESCARTAVEIS | B11: ='DRE DESPESAS'!B2 -> 0 | C11: ='DRE DESPESAS'!B3 -> 0 | N11: =SUM(B11:M11) -> 0
A12: GENEROS DE LIMPEZA | B12: ='DRE DESPESAS'!C2 -> 0 | C12: ='DRE DESPESAS'!A5 -> 0 | N12: =SUM(B12:M12) -> 0
A13: FRETES E CARRETOS S/ COMPRAS | B13: ='DRE DESPESAS'!D2 -> 0 | C13: ='DRE DESPESAS'!A6 -> 0 | N13: =SUM(B13:M13) -> 0
A14: HIGIENIZACAO - ECOLAB / DIVERSEY | B14: ='DRE DESPESAS'!E2 -> 0 | C14: ='DRE DESPESAS'!A7 -> 0 | N14: =SUM(B14:M14) -> 0
A15: TOTAL - CUSTO ALIMENTAR | B15: =SUM(B11:B14) -> 0 | C15: =SUM(C10:C14) -> 0 | D15: =SUM(D10:D14) -> 0 | E15: =SUM(E10:E14) -> 0 | F15: =SUM(F10:F14) -> 0 | G15: =SUM(G10:G14) -> 0 | H15: =SUM(H10:H14) -> 0 | I15: =SUM(I10:I14) -> 0 | J15: =SUM(J10:J14) -> 0 | ... M15: =SUM(M10:M14) -> 0 | N15: =SUM(B15:M15) -> 0
A16: % Sobre Receita Liquida | B16: =(B15/B7*100) -> #DIV/0! | C16: =(C15/C3*100) -> #DIV/0! | D16: =(D15/D3*100) -> #DIV/0! | E16: =(E15/E3*100) -> #DIV/0! | F16: =(F15/F3*100) -> #DIV/0! | G16: =(G15/G3*100) -> #DIV/0! | H16: =(H15/H3*100) -> #DIV/0! | I16: =(I15/I3*100) -> #DIV/0! | J16: =(J15/J3*100) -> #DIV/0! | ... M16: =(M15/M3*100) -> #DIV/0!
A17: MÃO DE OBRA
A18: SALARIOS | B18: ='DRE DESPESAS'!F2 -> 0 | C18: 1885.65 | N18: =SUM(B18:M18) -> 1885.65
A19: ALIMENTACAO | B19: ='DRE DESPESAS'!G2 -> 0 | N19: =SUM(B19:M19) -> 0
A20: VALE TRANSPORTE | B20: ='DRE DESPESAS'!H2 -> 0 | C20: 252 | N20: =SUM(B20:M20) -> 252
A21: TOTAL - MÃO DE OBRA | B21: =SUM(B18:B20) -> 0 | C21: =SUM(C18:C20) -> 2137.65 | D21: =SUM(D18:D20) -> 0 | E21: =SUM(E18:E20) -> 0 | F21: =SUM(F18:F20) -> 0 | G21: =SUM(G18:G20) -> 0 | H21: =SUM(H18:H20) -> 0 | I21: =SUM(I18:I20) -> 0 | ... M21: =SUM(M18:M20) -> 0 | N21: =SUM(B21:M21) -> 2137.65
A22: % Sobre Receita Líquida | B22: =B21/B7*100 -> #DIV/0! | C22: =C21/C7*100 -> #DIV/0! | D22: =D21/D7*100 -> #DIV/0! | E22: =E21/E7*100 -> #DIV/0! | F22: =F21/F7*100 -> #DIV/0! | G22: =G21/G7*100 -> #DIV/0! | H22: =H21/H7*100 -> #DIV/0! | I22: =I21/I7*100 -> #DIV/0! | ... M22: =M21/M7*100 -> #DIV/0!
A23: DESPESAS OPERACIONAIS
A24: ÁGUA | B24: ='DRE DESPESAS'!I2 -> 0 | N24: =SUM(B24:M24) -> 0
A25: LUZ (ENERGIA) | B25: ='DRE DESPESAS'!J2 -> 0 | N25: =SUM(B25:M25) -> 0
A26: MANUTENCOES E REPAROS | B26: ='DRE DESPESAS'!K2 -> 0 | N26: =SUM(B26:M26) -> 0
A27: INTERNET | B27: ='DRE DESPESAS'!L2 -> 0 | N27: =SUM(B27:M27) -> 0
A28: TELEFONE / FAX | B28: ='DRE DESPESAS'!M2 -> 0 | N28: =SUM(B28:M28) -> 0
A29: UNIFORMES | B29: ='DRE DESPESAS'!N2 -> 0 | N29: =SUM(B29:M29) -> 0
A30: UTENSILIOS | B30: ='DRE DESPESAS'!O2 -> 0 | N30: =SUM(B30:M30) -> 0
A31: EPI - PROTECAO INDIVIDUAL | B31: ='DRE DESPESAS'!P2 -> 0 | N31: =SUM(B31:M31) -> 0
A32: OUTROS CUSTOS GERAIS | B32: ='DRE DESPESAS'!Q2 -> 0 | C32: 14746.27 | N32: =SUM(B32:M32) -> 14746.27
A33: REEMBOLSO DE LOCOMOCAO | B33: ='DRE DESPESAS'!R2 -> 0 | N33: =SUM(B33:M33) -> 0
A34: TAXA DE ADM DO CARTÃO DE CRÉDITO | N34: =SUM(B34:M34) -> 0
A35: COPIAS E IMPRESSOES | B35: ='DRE DESPESAS'!S2 -> 0 | N35: =SUM(B35:M35) -> 0
A36: TOTAL - DESPESAS OPERACIONAIS | B36: =SUM(B24:B35) -> 0 | C36: =SUM(C24:C35) -> 14746.27 | D36: =SUM(D24:D35) -> 0 | E36: =SUM(E24:E35) -> 0 | F36: =SUM(F24:F35) -> 0 | G36: =SUM(G24:G35) -> 0 | H36: =SUM(H24:H35) -> 0 | I36: =SUM(I24:I35) -> 0 | ... M36: =SUM(M24:M35) -> 0 | N36: =SUM(B36:M36) -> 14746.27
A37: % Sobre Receita Líquida | B37: =B36/B7*100 -> #DIV/0! | C37: =C36/C7*100 -> #DIV/0! | D37: =D36/D7*100 -> #DIV/0! | E37: =E36/E7*100 -> #DIV/0! | F37: =F36/F7*100 -> #DIV/0! | G37: =G36/G7*100 -> #DIV/0! | H37: =H36/H7*100 -> #DIV/0! | I37: =I36/I7*100 -> #DIV/0! | ... M37: =M36/M7*100 -> #DIV/0!
A39: PROLABORE | B39: ='DRE DESPESAS'!T2 -> 0 | N39: =SUM(B39:M39) -> 0
A40: % Sobre Receita Líquida | B40: =B39/B7*100 -> #DIV/0! | C40: =C39/C7*100 -> #DIV/0! | D40: =D39/D7*100 -> #DIV/0! | E40: =E39/E7*100 -> #DIV/0! | F40: =F39/F7*100 -> #DIV/0! | G40: =G39/G7*100 -> #DIV/0! | H40: =H39/H7*100 -> #DIV/0! | I40: =I39/I7*100 -> #DIV/0! | ... M40: =M39/M7*100 -> #DIV/0!
A42: RESULTADO | B42: =B7-B15-B21-B36-B39 -> 0 | C42: =C7-C15-C21-C36-C39 -> -16883.92 | D42: =D7-D15-D21-D36-D39 -> 0 | E42: =E7-E15-E21-E36-E39 -> 0 | F42: =F7-F15-F21-F36-F39 -> 0 | G42: =G7-G15-G21-G36-G39 -> 0 | H42: =H7-H15-H21-H36-H39 -> 0 | I42: =I7-I15-I21-I36-I39 -> 0 | ... M42: =M7-M15-M21-M36-M39 -> 0 | N42: =SUM(B42:M42) -> -16883.92
...

Sheet SIMULADOR
B1: DIAS | C1: QTD DIÁRIA | D1: TOTAL | E1: VALOR MÉDIO | F1: TOTAL | H1: DESPESA | I1: DESPESA TOTAL | K1: LUCRO | L1: LUCRO TOTAL | N1: DESPESAS
A2: HAMBURGUER | B2: 12 | C2: 30 | D2: =B2*C2 -> 360 | E2: 20 | F2: =D2*E2 -> 7200 | H2: 9.83 | I2: =D2*H2 -> 3538.8 | K2: 10.17 | L2: =K2*D2 -> 3661.2 | N2: AGUA | O2: 1000
A3: BEBIDAS | B3: 12 | C3: 30 | D3: =B3*C3 -> 360 | E3: 5 | F3: =D3*E3 -> 1800 | H3: 2.1 | I3: =D3*H3 -> 756 | K3: 2.9 | L3: =K3*D3 -> 1044 | N3: LUZ | O3: 500
A4: FRITAS | B4: 12 | C4: 4 | D4: =B4*C4 -> 48 | E4: 18 | F4: =D4*E4 -> 864 | H4: 8 | I4: =D4*H4 -> 384 | K4: 10 | L4: =K4*D4 -> 480 | N4: GAS | O4: 90
F5: =SUM(F2:F4) -> 9864 | I5: =SUM(I2:I4) -> 4678.8 | L5: =SUM(L2:L4) -> 5185.2 | N5: PROLABORE | O5: 2520
O6: =SUM(O2:O5) -> 4110
J10: LUCRO MENSAL: | M10: =L5-O6 -> 1075.2

Sheet DRE DESPESAS
A1: ALIMENTICIOS | B1: DESCARTAVEIS | C1: LIMPEZA | D1: FRETES | E1: FAXINEIRA | F1: SALARIOS | G1: ALIMENT. PESSOAL | H1: VALE TRANSPORTE | I1: AGUA | J1: LUZ | K1: MANUTENCOES | L1: INTERNET | M1: TELEFONE | N1: UNIFORMES | O1: UTENSILIOS | P1: EPI | Q1: OUTROS CUSTOS GERAIS | R1: REEMBOLSO DE LOC. | S1: IMPRESSOES | T1: PROLABORE | U1: MES

Sheet DRE RECEITAS
A1: FATURAMENTO | B1: DINHEIRO | C1: CARTAO E PLANOS | D1: MES
