Workbook

Sheet 1ª SEG
A1: PLANILHA DE CONTROLE DIÁRIO
A2: DINHEIRO | F2: DATA:
A3: TOTAL EM DINHEIRO: | G3: FAT. LIQUIDO
A4: DESPESAS PAGAS COM O DINHEIRO DO CAIXA | F4: DINHEIRO | G4: =B3
F5: CARTÃO | G5: =E20
F6: IFOOD | G6: =E27
F7: FAT. TOTAL: | G7: =G4+G5+G6
F8: DESP. ALIMENTAR | G8: =B37
F9: DESP. MÃO DE OBRA | G9: =B43
F10: DESP. GERAIS | G10: =B58
A11: TOTAL: | B11: =B3-SUM(B5:B10) | F11: PROLABORE | G11: =B60
F12: LUCRO TOTAL: | G12: =G7-G8-G9-G10-G11
A14: CARTÃO DE CRÉDITO
A15: CARTÃO | B15: VALOR | C15: TAXA % | D15: DESCONTO | E15: VALOR LIQUIDO
A16: CRÉDITO | B16: 0 | C16: 3.09 | D16: =B16*C16/100 | E16: =B16-D16
A17: DÉBITO | B17: 0 | C17: 1.95 | D17: =B17*C17/100 | E17: =B17-D17
A18: CRÉDITO CARLOS | B18: 0 | C18: 2 | D18: =B18*C18/100 | E18: =B18-D18
A19: DÉBITO CARLOS | B19: 0 | C19: 2 | D19: =B19*C19/100 | E19: =B19-D19
A20: TOTAL EM CARTÃO | B20: =SUM(B16:B19) | D20: =SUM(D16:D19) | E20: =SUM(E16:E19)
A23: IFOOD
A24: CARTÃO | B24: VALOR | C24: TAXA % | D24: DESCONTO | E24: VALOR LIQUIDO ONLINE
A25: IFOOD - PAGO LOJA | C25: 12 | D25: =B25*C25/100
A26: IFOOD - PAGO ONLINE | B26: 0 | C26: 15.5 | D26: =B26*C26/100 | E26: =B26-D27 | F26: VALOR PAGO ONLINE E COM TODOS OS DESCONTOS
A27: TOTAL EM IFOOD | B27: =SUM(B25:B26) | D27: =SUM(D25:D26) | E27: =SUM(E25:E26)
A30: DESPESAS NO DIA | C30: OBSERVAÇÕES
A31: CUSTO ALIMENTAR
A32: GENEROS ALIMENTICIOS | B32: 0
A33: GENEROS DESCARTAVEIS | B33: 0
A34: GENEROS DE LIMPEZA
B35: 0
A36: HIGIENIZACAO - TIA DA LIMPEZA | B36: 0
A37: TOTAL - CUSTO ALIMENTAR | B37: =SUM(B32:B36)
A39: MÃO DE OBRA
A40: SALARIO DOS FUNCIONÁRIOS | B40: 0
A41: ALIMENTACAO | B41: 0
A42: VALE TRANSPORTE
A43: TOTAL - MÃO DE OBRA | B43: =SUM(B40:B42)
A45: DESPESAS OPERACIONAIS
A46: ÁGUA | B46: 0
A47: LUZ (ENERGIA)
...

Sheet 1ª TER
A1: PLANILHA DE CONTROLE DIÁRIO
A2: DINHEIRO | F2: DATA:
A3: TOTAL EM DINHEIRO: | G3: FAT. LIQUIDO
A4: DESPESAS PAGAS COM O DINHEIRO DO CAIXA | F4: DINHEIRO | G4: =B3
F5: CARTÃO | G5: =E20
F6: IFOOD | G6: =E27
F7: FAT. TOTAL: | G7: =G4+G5+G6
F8: DESP. ALIMENTAR | G8: =B37
F9: DESP. MÃO DE OBRA | G9: =B43
F10: DESP. GERAIS | G10: =B58
A11: TOTAL: | F11: PROLABORE | G11: =B60
F12: LUCRO TOTAL: | G12: =G7-G8-G9-G10-G11
A14: CARTÃO DE CRÉDITO
A15: CARTÃO | B15: VALOR | C15: TAXA % | D15: DESCONTO | E15: VALOR LIQUIDO
A16: CRÉDITO | B16: 0 | C16: 3.09 | D16: =B16*C16/100 | E16: =B16-D16
A17: DÉBITO | B17: 0 | C17: 1.95 | D17: =B17*C17/100 | E17: =B17-D17
A18: CRÉDITO CARLOS | B18: 0 | C18: 2 | D18: =B18*C18/100 | E18: =B18-D18
A19: DÉBITO CARLOS | B19: 0 | C19: 2 | D19: =B19*C19/100 | E19: =B19-D19
A20: TOTAL EM CARTÃO | B20: =SUM(B16:B19) | D20: =SUM(D16:D19) | E20: =SUM(E16:E19)
A23: IFOOD
A24: CARTÃO | B24: VALOR | C24: TAXA % | D24: DESCONTO | E24: VALOR LIQUIDO ONLINE | F24: VALOR PAGO ONLINE E COM TODOS OS DESCONTOS
A25: IFOOD - PAGO LOJA | B25: 0 | C25: 12 | D25: =B25*C25/100
A26: IFOOD - PAGO ONLINE | B26: 0 | C26: 15.5 | D26: =B26*C26/100 | E26: =B26-D27
A27: TOTAL EM IFOOD | B27: =SUM(B25:B26) | D27: =SUM(D25:D26) | E27: =SUM(E25:E26)
A30: DESPESAS NO DIA | C30: OBSERVAÇÕES
A31: CUSTO ALIMENTAR
A32: GENEROS ALIMENTICIOS | B32: 0
A33: GENEROS DESCARTAVEIS | B33: 0
A34: GENEROS DE LIMPEZA | B34: 0
A35: FRETES E CARRETOS | B35: 0
A36: HIGIENIZACAO - TIA DA LIMPEZA | B36: 0
A37: TOTAL - CUSTO ALIMENTAR | B37: =SUM(B32:B36)
A39: MÃO DE OBRA
A40: SALARIO DOS FUNCIONÁRIOS | B40: 0
A41: ALIMENTACAO | B41: 0
A42: VALE TRANSPORTE
A43: TOTAL - MÃO DE OBRA | B43: =SUM(B40:B42)
A45: DESPESAS OPERACIONAIS
A46: ÁGUA | B46: 0
A47: LUZ (ENERGIA)
...

Sheet 1ª QUA
A1: PLANILHA DE CONTROLE DIÁRIO
A2: DINHEIRO | F2: DATA: | G2: 45658
A3: TOTAL EM DINHEIRO: | G3: FAT. LIQUIDO
A4: DESPESAS PAGAS COM O DINHEIRO DO CAIXA | F4: DINHEIRO | G4: =B3
F5: CARTÃO | G5: =E20
F6: IFOOD | G6: =E27
F7: FAT. TOTAL: | G7: =G4+G5+G6
F8: DESP. ALIMENTAR | G8: =B37
F9: DESP. MÃO DE OBRA | G9: =B43
F10: DESP. GERAIS | G10: =B58
A11: TOTAL: | B11: =B3-SUM(B5:B9) | F11: PROLABORE | G11: =B60
F12: LUCRO TOTAL: | G12: =G7-G8-G9-G10-G11
A14: CARTÃO DE CRÉDITO
A15: CARTÃO | B15: VALOR | C15: TAXA % | D15: DESCONTO | E15: VALOR LIQUIDO
A16: CRÉDITO | B16: 0 | C16: 3.09 | D16: =B16*C16/100 | E16: =B16-D16
A17: DÉBITO | B17: 0 | C17: 1.95 | D17: =B17*C17/100 | E17: =B17-D17
A18: CRÉDITO CARLOS | B18: 0 | C18: 2 | D18: =B18*C18/100 | E18: =B18-D18
A19: DÉBITO CARLOS | B19: 0 | C19: 2 | D19: =B19*C19/100 | E19: =B19-D19
A20: TOTAL EM CARTÃO | B20: =SUM(B16:B19) | D20: =SUM(D16:D19) | E20: =SUM(E16:E19)
A23: IFOOD
A24: CARTÃO | B24: VALOR | C24: TAXA % | D24: DESCONTO | E24: VALOR LIQUIDO ONLINE
A25: IFOOD - PAGO LOJA | B25: 0 | C25: 12 | D25: =B25*C25/100
A26: IFOOD - PAGO ONLINE | B26: 0 | C26: 15.5 | D26: =B26*C26/100 | E26: =B26-D27 | F26: VALOR PAGO ONLINE E COM TODOS OS DESCONTOS
A27: TOTAL EM IFOOD | B27: =SUM(B25:B26) | D27: =SUM(D25:D26) | E27: =SUM(E25:E26)
A30: DESPESAS NO DIA | C30: OBSERVAÇÕES
A31: CUSTO ALIMENTAR
A32: GENEROS ALIMENTICIOS | B32: 0
A33: GENEROS DESCARTAVEIS
A34: GENEROS DE LIMPEZA | B34: 0
A35: FRETES E CARRETOS | B35: 0
A36: HIGIENIZACAO - TIA DA LIMPEZA | B36: 0
A37: TOTAL - CUSTO ALIMENTAR | B37: =SUM(B32:B36)
A39: MÃO DE OBRA
A40: SALARIO DOS FUNCIONÁRIOS
A41: ALIMENTACAO | B41: 0
A42: VALE TRANSPORTE
A43: TOTAL - MÃO DE OBRA | B43: =SUM(B40:B42)
A45: DESPESAS OPERACIONAIS
A46: ÁGUA | B46: 0
A47: LUZ (ENERGIA) | B47: 0
...

Sheet 1º QUI
A1: PLANILHA DE CONTROLE DIÁRIO
A2: DINHEIRO | F2: DATA:
A3: TOTAL EM DINHEIRO: | G3: FAT. LIQUIDO
A4: DESPESAS PAGAS COM O DINHEIRO DO CAIXA | F4: DINHEIRO | G4: =B3
F5: CARTÃO | G5: =E20
F6: IFOOD | G6: =E27
F7: FAT. TOTAL: | G7: =G4+G5+G6
F8: DESP. ALIMENTAR | G8: =B37
F9: DESP. MÃO DE OBRA | G9: =B43
F10: DESP. GERAIS | G10: =B58
A11: TOTAL: | B11: =B3-SUM(B5:B10) | F11: PROLABORE | G11: =B60
F12: LUCRO TOTAL: | G12: =G7-G8-G9-G10-G11
A14: CARTÃO DE CRÉDITO
A15: CARTÃO | B15: VALOR | C15: TAXA % | D15: DESCONTO | E15: VALOR LIQUIDO
A16: CRÉDITO | B16: 0 | C16: 3.09 | D16: =B16*C16/100 | E16: =B16-D16
A17: DÉBITO | B17: 0 | C17: 1.95 | D17: =B17*C17/100 | E17: =B17-D17
A18: CRÉDITO CARLOS | B18: 0 | C18: 2 | D18: =B18*C18/100 | E18: =B18-D18
A19: DÉBITO CARLOS | B19: 0 | C19: 2 | D19: =B19*C19/100 | E19: =B19-D19
A20: TOTAL EM CARTÃO | B20: =SUM(B16:B19) | D20: =SUM(D16:D19) | E20: =SUM(E16:E19)
A23: IFOOD
A24: CARTÃO | B24: VALOR | C24: TAXA % | D24: DESCONTO | E24: VALOR LIQUIDO ONLINE
A25: IFOOD - PAGO LOJA | C25: 12 | D25: =B25*C25/100
A26: IFOOD - PAGO ONLINE | B26: 0 | C26: 15.5 | D26: =B26*C26/100 | E26: =B26-D27 | F26: VALOR PAGO ONLINE E COM TODOS OS DESCONTOS
A27: TOTAL EM IFOOD | B27: =SUM(B25:B26) | D27: =SUM(D25:D26) | E27: =SUM(E25:E26)
A30: DESPESAS NO DIA | C30: OBSERVAÇÕES
A31: CUSTO ALIMENTAR
A32: GENEROS ALIMENTICIOS | B32: 0
A33: GENEROS DESCARTAVEIS | B33: 0
A34: GENEROS DE LIMPEZA | B34: 0
B35: 0
A36: HIGIENIZACAO - TIA DA LIMPEZA | B36: 0
A37: TOTAL - CUSTO ALIMENTAR | B37: =SUM(B32:B36)
A39: MÃO DE OBRA
A40: SALARIO DOS FUNCIONÁRIOS
A41: ALIMENTACAO | B41: 0
A42: VALE TRANSPORTE
A43: TOTAL - MÃO DE OBRA | B43: =SUM(B40:B42)
A45: DESPESAS OPERACIONAIS
A46: ÁGUA | B46: 0
A47: LUZ (ENERGIA) | B47: 0
...

Sheet 1º SEX
A1: PLANILHA DE CONTROLE DIÁRIO
A2: DINHEIRO | F2: DATA:
A3: TOTAL EM DINHEIRO: | G3: FAT. LIQUIDO
A4: DESPESAS PAGAS COM O DINHEIRO DO CAIXA | F4: DINHEIRO | G4: =B3
F5: CARTÃO | G5: =E20
F6: IFOOD | G6: =E27
F7: FAT. TOTAL: | G7: =G4+G5+G6
F8: DESP. ALIMENTAR | G8: =B37
F9: DESP. MÃO DE OBRA | G9: =B43
F10: DESP. GERAIS | G10: =B58
A11: TOTAL: | B11: =B3-SUM(B5:B10) | F11: PROLABORE | G11: =B60
F12: LUCRO TOTAL: | G12: =G7-G8-G9-G10-G11
A14: CARTÃO DE CRÉDITO
A15: CARTÃO | B15: VALOR | C15: TAXA % | D15: DESCONTO | E15: VALOR LIQUIDO
A16: CRÉDITO | B16: 0 | C16: 3.09 | D16: =B16*C16/100 | E16: =B16-D16
A17: DÉBITO | B17: 0 | C17: 1.95 | D17: =B17*C17/100 | E17: =B17-D17
A18: CRÉDITO CARLOS | B18: 0 | C18: 2 | D18: =B18*C18/100 | E18: =B18-D18
A19: DÉBITO CARLOS | B19: 0 | C19: 2 | D19: =B19*C19/100 | E19: =B19-D19
A20: TOTAL EM CARTÃO | B20: =SUM(B16:B19) | D20: =SUM(D16:D19) | E20: =SUM(E16:E19)
A23: IFOOD
A24: CARTÃO | B24: VALOR | C24: TAXA % | D24: DESCONTO | E24: VALOR LIQUIDO ONLINE
A25: IFOOD - PAGO LOJA | C25: 12 | D25: =B25*C25/100
A26: IFOOD - PAGO ONLINE | C26: 15.5 | D26: =B26*C26/100 | E26: =B26-D27 | F26: VALOR PAGO ONLINE E COM TODOS OS DESCONTOS
A27: TOTAL EM IFOOD | B27: =SUM(B25:B26) | D27: =SUM(D25:D26) | E27: =SUM(E25:E26)
A30: DESPESAS NO DIA | C30: OBSERVAÇÕES
A31: CUSTO ALIMENTAR
A32: GENEROS ALIMENTICIOS | B32: 0
A33: GENEROS DESCARTAVEIS | B33: 0
A34: GENEROS DE LIMPEZA | B34: 0
B35: 0
A36: HIGIENIZACAO - TIA DA LIMPEZA | B36: 0
A37: TOTAL - CUSTO ALIMENTAR | B37: =SUM(B32:B36)
A39: MÃO DE OBRA
A40: SALARIO DOS FUNCIONÁRIOS | B40: 0
A41: ALIMENTACAO | B41: 0
A42: VALE TRANSPORTE | B42: 0
A43: TOTAL - MÃO DE OBRA | B43: =SUM(B40:B42)
A45: DESPESAS OPERACIONAIS
A46: ÁGUA | B46: 0
A47: LUZ (ENERGIA) | B47: 0
...

Sheet 2º SEG
A1: PLANILHA DE CONTROLE DIÁRIO
A2: DINHEIRO | F2: DATA: | G2: 45663
A3: TOTAL EM DINHEIRO: | G3: FAT. LIQUIDO
A4: DESPESAS PAGAS COM O DINHEIRO DO CAIXA | F4: DINHEIRO | G4: =B3
F5: CARTÃO | G5: =E20
F6: IFOOD | G6: =E27
F7: FAT. TOTAL: | G7: =G4+G5+G6
F8: DESP. ALIMENTAR | G8: =B37
F9: DESP. MÃO DE OBRA | G9: =B43
F10: DESP. GERAIS | G10: =B58
A11: TOTAL: | B11: =B3-SUM(B5:B9) | F11: PROLABORE | G11: =B60
F12: LUCRO TOTAL: | G12: =G7-G8-G9-G10-G11
A14: CARTÃO DE CRÉDITO
A15: CARTÃO | B15: VALOR | C15: TAXA % | D15: DESCONTO | E15: VALOR LIQUIDO
A16: CRÉDITO | B16: 0 | C16: 3.09 | D16: =B16*C16/100 | E16: =B16-D16
A17: DÉBITO | B17: 0 | C17: 1.95 | D17: =B17*C17/100 | E17: =B17-D17
A18: CRÉDITO CARLOS | B18: 0 | C18: 2 | D18: =B18*C18/100 | E18: =B18-D18
A19: DÉBITO CARLOS | B19: 0 | C19: 2 | D19: =B19*C19/100 | E19: =B19-D19
A20: TOTAL EM CARTÃO | B20: =SUM(B16:B19) | D20: =SUM(D16:D19) | E20: =SUM(E16:E19)
A23: IFOOD
A24: CARTÃO | B24: VALOR | C24: TAXA % | D24: DESCONTO | E24: VALOR LIQUIDO ONLINE
A25: IFOOD - PAGO LOJA | C25: 12 | D25: =B25*C25/100
A26: IFOOD - PAGO ONLINE | C26: 15.5 | D26: =B26*C26/100 | E26: =B26-D27 | F26: VALOR PAGO ONLINE E COM TODOS OS DESCONTOS
A27: TOTAL EM IFOOD | B27: =SUM(B25:B26) | D27: =SUM(D25:D26) | E27: =SUM(E25:E26)
A30: DESPESAS NO DIA | C30: OBSERVAÇÕES
A31: CUSTO ALIMENTAR
A32: GENEROS ALIMENTICIOS
A33: GENEROS DESCARTAVEIS
A34: GENEROS DE LIMPEZA
A35: FRETES E CARRETOS
A36: HIGIENIZACAO - TIA DA LIMPEZA | B36: 180
A37: TOTAL - CUSTO ALIMENTAR | B37: =SUM(B32:B36)
A39: MÃO DE OBRA
A40: SALARIO DOS FUNCIONÁRIOS
A41: ALIMENTACAO
A42: VALE TRANSPORTE
A43: TOTAL - MÃO DE OBRA | B43: =SUM(B40:B42)
A45: DESPESAS OPERACIONAIS
A46: ÁGUA | B46: 0
A47: LUZ (ENERGIA) | B47: 0
...

Sheet 2º TER
A1: PLANILHA DE CONTROLE DIÁRIO
A2: DINHEIRO | F2: DATA: | G2: 07/01/025
A3: TOTAL EM DINHEIRO: | G3: FAT. LIQUIDO
A4: DESPESAS PAGAS COM O DINHEIRO DO CAIXA | F4: DINHEIRO | G4: =B3
F5: CARTÃO | G5: =E20
F6: IFOOD | G6: =E27
F7: FAT. TOTAL: | G7: =G4+G5+G6
F8: DESP. ALIMENTAR | G8: =B37
F9: DESP. MÃO DE OBRA | G9: =B43
F10: DESP. GERAIS | G10: =B58
A11: TOTAL: | B11: =B3-SUM(B5:B9) | F11: PROLABORE | G11: =B60
F12: LUCRO TOTAL: | G12: =G7-G8-G9-G10-G11
A14: CARTÃO DE CRÉDITO
A15: CARTÃO | B15: VALOR | C15: TAXA % | D15: DESCONTO | E15: VALOR LIQUIDO
A16: CRÉDITO | B16: 0 | C16: 3.09 | D16: =B16*C16/100 | E16: =B16-D16
A17: DÉBITO | B17: 0 | C17: 1.95 | D17: =B17*C17/100 | E17: =B17-D17
A18: CRÉDITO CARLOS | B18: 0 | C18: 2 | D18: =B18*C18/100 | E18: =B18-D18
A19: DÉBITO CARLOS | B19: 0 | C19: 2 | D19: =B19*C19/100 | E19: =B19-D19
A20: TOTAL EM CARTÃO | B20: =SUM(B16:B19) | D20: =SUM(D16:D19) | E20: =SUM(E16:E19)
A23: IFOOD
A24: CARTÃO | B24: VALOR | C24: TAXA % | D24: DESCONTO | E24: VALOR LIQUIDO ONLINE
A25: IFOOD - PAGO LOJA | C25: 12 | D25: =B25*C25/100
A26: IFOOD - PAGO ONLINE | C26: 15.5 | D26: =B26*C26/100 | E26: =B26-D27 | F26: VALOR PAGO ONLINE E COM TODOS OS DESCONTOS
A27: TOTAL EM IFOOD | B27: =SUM(B25:B26) | D27: =SUM(D25:D26) | E27: =SUM(E25:E26)
A30: DESPESAS NO DIA | C30: OBSERVAÇÕES
A31: CUSTO ALIMENTAR
A32: GENEROS ALIMENTICIOS
A33: GENEROS DESCARTAVEIS
A34: GENEROS DE LIMPEZA
A35: FRETES E CARRETOS
A36: HIGIENIZACAO - TIA DA LIMPEZA
A37: TOTAL - CUSTO ALIMENTAR | B37: =SUM(B32:B36)
A39: MÃO DE OBRA
A40: SALARIO DOS FUNCIONÁRIOS
A41: ALIMENTACAO
A42: VALE TRANSPORTE
A43: TOTAL - MÃO DE OBRA | B43: =SUM(B40:B42)
A45: DESPESAS OPERACIONAIS
A46: ÁGUA | B46: 0
A47: LUZ (ENERGIA) | B47: 0
...

Sheet 2º QUA
A1: PLANILHA DE CONTROLE DIÁRIO
A2: DINHEIRO | F2: DATA: | G2: 45665
A3: TOTAL EM DINHEIRO: | G3: FAT. LIQUIDO
A4: DESPESAS PAGAS COM O DINHEIRO DO CAIXA | F4: DINHEIRO | G4: =B3
F5: CARTÃO | G5: =E20
F6: IFOOD | G6: =E27
F7: FAT. TOTAL: | G7: =G4+G5+G6
F8: DESP. ALIMENTAR | G8: =B37
F9: DESP. MÃO DE OBRA | G9: =B43
F10: DESP. GERAIS | G10: =B58
A11: TOTAL: | B11: =B3-SUM(B5:B9) | F11: PROLABORE | G11: =B60
F12: LUCRO TOTAL: | G12: =G7-G8-G9-G10-G11
A14: CARTÃO DE CRÉDITO
A15: CARTÃO | B15: VALOR | C15: TAXA % | D15: DESCONTO | E15: VALOR LIQUIDO
A16: CRÉDITO | B16: 0 | C16: 3.09 | D16: =B16*C16/100 | E16: =B16-D16
A17: DÉBITO | B17: 0 | C17: 1.95 | D17: =B17*C17/100 | E17: =B17-D17
A18: CRÉDITO CARLOS | B18: 0 | C18: 2 | D18: =B18*C18/100 | E18: =B18-D18
A19: DÉBITO CARLOS | B19: 0 | C19: 2 | D19: =B19*C19/100 | E19: =B19-D19
A20: TOTAL EM CARTÃO | B20: =SUM(B16:B19) | D20: =SUM(D16:D19) | E20: =SUM(E16:E19)
A23: IFOOD
A24: CARTÃO | B24: VALOR | C24: TAXA % | D24: DESCONTO | E24: VALOR LIQUIDO ONLINE
A25: IFOOD - PAGO LOJA | C25: 12 | D25: =B25*C25/100
A26: IFOOD - PAGO ONLINE | C26: 15.5 | D26: =B26*C26/100 | E26: =B26-D27 | F26: VALOR PAGO ONLINE E COM TODOS OS DESCONTOS
A27: TOTAL EM IFOOD | B27: =SUM(B25:B26) | D27: =SUM(D25:D26) | E27: =SUM(E25:E26)
A30: DESPESAS NO DIA | C30: OBSERVAÇÕES
A31: CUSTO ALIMENTAR
A32: GENEROS ALIMENTICIOS
A33: GENEROS DESCARTAVEIS
A34: GENEROS DE LIMPEZA
A35: FRETES E CARRETOS
A36: HIGIENIZACAO - TIA DA LIMPEZA | B36: 0
A37: TOTAL - CUSTO ALIMENTAR | B37: =SUM(B32:B36)
A39: MÃO DE OBRA
A40: SALARIO DOS FUNCIONÁRIOS
A41: ALIMENTACAO | B41: 0
A42: VALE TRANSPORTE
A43: TOTAL - MÃO DE OBRA | B43: =SUM(B40:B42)
A45: DESPESAS OPERACIONAIS
A46: ÁGUA | B46: 0
A47: LUZ (ENERGIA) | B47: 0
...

Sheet 2º QUI
A1: PLANILHA DE CONTROLE DIÁRIO
A2: DINHEIRO | F2: DATA:
A3: TOTAL EM DINHEIRO: | G3: FAT. LIQUIDO
A4: DESPESAS PAGAS COM O DINHEIRO DO CAIXA | F4: DINHEIRO | G4: =B3
F5: CARTÃO | G5: =E20
F6: IFOOD | G6: =E27
F7: FAT. TOTAL: | G7: =G4+G5+G6
F8: DESP. ALIMENTAR | G8: =B37
F9: DESP. MÃO DE OBRA | G9: =B43
F10: DESP. GERAIS | G10: =B58
A11: TOTAL: | B11: =B3-SUM(B5:B10) | F11: PROLABORE | G11: =B60
F12: LUCRO TOTAL: | G12: =G7-G8-G9-G10-G11
A14: CARTÃO DE CRÉDITO
A15: CARTÃO | B15: VALOR | C15: TAXA % | D15: DESCONTO | E15: VALOR LIQUIDO
A16: CRÉDITO | B16: 0 | C16: 3.09 | D16: =B16*C16/100 | E16: =B16-D16
A17: DÉBITO | B17: 0 | C17: 1.95 | D17: =B17*C17/100 | E17: =B17-D17
A18: CRÉDITO CARLOS | B18: 0 | C18: 2 | D18: =B18*C18/100 | E18: =B18-D18
A19: DÉBITO CARLOS | B19: 0 | C19: 2 | D19: =B19*C19/100 | E19: =B19-D19
A20: TOTAL EM CARTÃO | B20: =SUM(B16:B19) | D20: =SUM(D16:D19) | E20: =SUM(E16:E19)
A23: IFOOD
A24: CARTÃO | B24: VALOR | C24: TAXA % | D24: DESCONTO | E24: VALOR LIQUIDO ONLINE
A25: IFOOD - PAGO LOJA | C25: 12 | D25: =B25*C25/100
A26: IFOOD - PAGO ONLINE | C26: 15.5 | D26: =B26*C26/100 | E26: =B26-D27 | F26: VALOR PAGO ONLINE E COM TODOS OS DESCONTOS
A27: TOTAL EM IFOOD | B27: =SUM(B25:B26) | D27: =SUM(D25:D26) | E27: =SUM(E25:E26)
A30: DESPESAS NO DIA | C30: OBSERVAÇÕES
A31: CUSTO ALIMENTAR
A32: GENEROS ALIMENTICIOS
A33: GENEROS DESCARTAVEIS
A34: GENEROS DE LIMPEZA
A36: HIGIENIZACAO - TIA DA LIMPEZA
A37: TOTAL - CUSTO ALIMENTAR | B37: =SUM(B32:B36)
A39: MÃO DE OBRA
A40: SALARIO DOS FUNCIONÁRIOS
A41: ALIMENTACAO
A42: VALE TRANSPORTE
A43: TOTAL - MÃO DE OBRA | B43: =SUM(B40:B42)
A45: DESPESAS OPERACIONAIS
A46: ÁGUA
A47: LUZ (ENERGIA)
A48: GÁS
...

Sheet 2º SEX
A1: PLANILHA DE CONTROLE DIÁRIO
A2: DINHEIRO | F2: DATA: | G2: 45667
A3: TOTAL EM DINHEIRO: | G3: FAT. LIQUIDO
A4: DESPESAS PAGAS COM O DINHEIRO DO CAIXA | F4: DINHEIRO | G4: =B3
F5: CARTÃO | G5: =E20
F6: IFOOD | G6: =E27
F7: FAT. TOTAL: | G7: =G4+G5+G6
F8: DESP. ALIMENTAR | G8: =B37
F9: DESP. MÃO DE OBRA | G9: =B43
F10: DESP. GERAIS | G10: =B58
A11: TOTAL: | B11: =B3-SUM(B5:B10) | F11: PROLABORE | G11: =B60
F12: LUCRO TOTAL: | G12: =G7-G8-G9-G10-G11
A14: CARTÃO DE CRÉDITO
A15: CARTÃO | B15: VALOR | C15: TAXA % | D15: DESCONTO | E15: VALOR LIQUIDO
A16: CRÉDITO | B16: 0 | C16: 3.09 | D16: =B16*C16/100 | E16: =B16-D16
A17: DÉBITO | B17: 0 | C17: 1.95 | D17: =B17*C17/100 | E17: =B17-D17
A18: CRÉDITO CARLOS | B18: 0 | C18: 2 | D18: =B18*C18/100 | E18: =B18-D18
A19: DÉBITO CARLOS | B19: 0 | C19: 2 | D19: =B19*C19/100 | E19: =B19-D19
A20: TOTAL EM CARTÃO | B20: =SUM(B16:B19) | D20: =SUM(D16:D19) | E20: =SUM(E16:E19)
A23: IFOOD
A24: CARTÃO | B24: VALOR | C24: TAXA % | D24: DESCONTO | E24: VALOR LIQUIDO ONLINE
A25: IFOOD - PAGO LOJA | C25: 12 | D25: =B25*C25/100
A26: IFOOD - PAGO ONLINE | C26: 15.5 | D26: =B26*C26/100 | E26: =B26-D27 | F26: VALOR PAGO ONLINE E COM TODOS OS DESCONTOS
A27: TOTAL EM IFOOD | B27: =SUM(B25:B26) | D27: =SUM(D25:D26) | E27: =SUM(E25:E26)
A30: DESPESAS NO DIA | C30: OBSERVAÇÕES
A31: CUSTO ALIMENTAR
A32: GENEROS ALIMENTICIOS
A33: GENEROS DESCARTAVEIS
A34: GENEROS DE LIMPEZA
A35: FRETES E CARRETOS
A36: HIGIENIZACAO - TIA DA LIMPEZA
A37: TOTAL - CUSTO ALIMENTAR | B37: =SUM(B32:B36)
A39: MÃO DE OBRA
A40: SALARIO DOS FUNCIONÁRIOS
A41: ALIMENTACAO
A42: VALE TRANSPORTE
A43: TOTAL - MÃO DE OBRA | B43: =SUM(B40:B42)
A45: DESPESAS OPERACIONAIS
A46: ÁGUA
A47: LUZ (ENERGIA)
...

Sheet 3º SEG
A1: PLANILHA DE CONTROLE DIÁRIO
A2: DINHEIRO | F2: DATA: | G2: 45670
A3: TOTAL EM DINHEIRO: | B3: 3540 | G3: FAT. LIQUIDO
A4: DESPESAS PAGAS COM O DINHEIRO DO CAIXA | F4: DINHEIRO | G4: =B3
F5: CARTÃO | G5: =E20
F6: IFOOD | G6: =E27
F7: FAT. TOTAL: | G7: =G4+G5+G6
F8: DESP. ALIMENTAR | G8: =B37
F9: DESP. MÃO DE OBRA | G9: =B43
F10: DESP. GERAIS | G10: =B58
A11: TOTAL: | B11: =B3-SUM(B5:B10) | F11: PROLABORE | G11: =B60
F12: LUCRO TOTAL: | G12: =G7-G8-G9-G10-G11
A14: CARTÃO E PLANOS
A15: CARTÃO | B15: VALOR | C15: TAXA % | D15: DESCONTO | E15: VALOR LIQUIDO
A16: CRÉDITO | B16: 5760.85 | C16: 0 | D16: =B16*C16/100 | E16: =B16-D16
A17: PLANOS | B17: 171.02 | C17: 0 | D17: =B17*C17/100 | E17: =B17-D17
C18: 0 | D18: =B18*C18/100 | E18: =B18-D18
B19: 0 | C19: 0 | D19: =B19*C19/100 | E19: =B19-D19
A20: TOTAL EM CARTÃO | B20: =SUM(B16:B19) | D20: =SUM(D16:D19) | E20: =SUM(E16:E19)
A23: PLANOS
A24: CARTÃO | B24: VALOR | C24: TAXA % | D24: DESCONTO | E24: VALOR LIQUIDO ONLINE
A25: IFOOD - PAGO LOJA | D25: =B25*C25/100
A26: IFOOD - PAGO ONLINE | D26: =B26*C26/100 | E26: =B26-D27 | F26: VALOR PAGO ONLINE E COM TODOS OS DESCONTOS
A27: TOTAL EM IFOOD | B27: =SUM(B25:B26) | D27: =SUM(D25:D26) | E27: =SUM(E25:E26)
A30: DESPESAS NO DIA | C30: OBSERVAÇÕES
A31: CUSTO ALIMENTAR
A32: GENEROS ALIMENTICIOS
A33: GENEROS DESCARTAVEIS
A34: GENEROS DE LIMPEZA
A35: FRETES E CARRETOS
A36: HIGIENIZACAO - TIA DA LIMPEZA
A37: TOTAL - CUSTO ALIMENTAR | B37: =SUM(B32:B36)
A39: MÃO DE OBRA
A40: SALARIO DOS FUNCIONÁRIOS | B40: 962.36
A41: ALIMENTACAO
A42: VALE TRANSPORTE | B42: 277.2
A43: TOTAL - MÃO DE OBRA | B43: =SUM(B40:B42)
A45: DESPESAS OPERACIONAIS
A46: ÁGUA
A47: LUZ (ENERGIA)
...

Sheet 3º TER
A1: PLANILHA DE CONTROLE DIÁRIO
A2: DINHEIRO | F2: DATA:
A3: TOTAL EM DINHEIRO: | G3: FAT. LIQUIDO
A4: DESPESAS PAGAS COM O DINHEIRO DO CAIXA | F4: DINHEIRO | G4: =B3
F5: CARTÃO | G5: =E20
F6: IFOOD | G6: =E27
F7: FAT. TOTAL: | G7: =G4+G5+G6
F8: DESP. ALIMENTAR | G8: =B37
F9: DESP. MÃO DE OBRA | G9: =B43
F10: DESP. GERAIS | G10: =B58
A11: TOTAL: | B11: =B3-SUM(B5:B9) | F11: PROLABORE | G11: =B60
F12: LUCRO TOTAL: | G12: =G7-G8-G9-G10-G11
A14: CARTÃO DE CRÉDITO
A15: CARTÃO | B15: VALOR | C15: TAXA % | D15: DESCONTO | E15: VALOR LIQUIDO
A16: CRÉDITO | B16: 0 | C16: 3.09 | D16: =B16*C16/100 | E16: =B16-D16
A17: DÉBITO | B17: 0 | C17: 1.95 | D17: =B17*C17/100 | E17: =B17-D17
A18: CRÉDITO CARLOS | B18: 0 | C18: 2 | D18: =B18*C18/100 | E18: =B18-D18
A19: DÉBITO CARLOS | B19: 0 | C19: 2 | D19: =B19*C19/100 | E19: =B19-D19
A20: TOTAL EM CARTÃO | B20: =SUM(B16:B19) | D20: =SUM(D16:D19) | E20: =SUM(E16:E19)
A23: IFOOD
A24: CARTÃO | B24: VALOR | C24: TAXA % | D24: DESCONTO | E24: VALOR LIQUIDO ONLINE
A25: IFOOD - PAGO LOJA | C25: 12 | D25: =B25*C25/100
A26: IFOOD - PAGO ONLINE | C26: 15.5 | D26: =B26*C26/100 | E26: =B26-D27 | F26: VALOR PAGO ONLINE E COM TODOS OS DESCONTOS
A27: TOTAL EM IFOOD | B27: =SUM(B25:B26) | D27: =SUM(D25:D26) | E27: =SUM(E25:E26)
A30: DESPESAS NO DIA | C30: OBSERVAÇÕES
A31: CUSTO ALIMENTAR
A32: GENEROS ALIMENTICIOS
A33: GENEROS DESCARTAVEIS
A34: GENEROS DE LIMPEZA
A35: FRETES E CARRETOS
A36: HIGIENIZACAO - TIA DA LIMPEZA
A37: TOTAL - CUSTO ALIMENTAR | B37: =SUM(B32:B36)
A39: MÃO DE OBRA
A40: SALARIO DOS FUNCIONÁRIOS
A41: ALIMENTACAO
A42: VALE TRANSPORTE
A43: TOTAL - MÃO DE OBRA | B43: =SUM(B40:B42)
A45: DESPESAS OPERACIONAIS
A46: ÁGUA
A47: LUZ (ENERGIA)
...

Sheet 3º QUA
A1: PLANILHA DE CONTROLE DIÁRIO
A2: DINHEIRO | F2: DATA:
A3: TOTAL EM DINHEIRO: | G3: FAT. LIQUIDO
A4: DESPESAS PAGAS COM O DINHEIRO DO CAIXA | F4: DINHEIRO | G4: =B3
F5: CARTÃO | G5: =E20
F6: IFOOD | G6: =E27
F7: FAT. TOTAL: | G7: =G4+G5+G6
F8: DESP. ALIMENTAR | G8: =B37
F9: DESP. MÃO DE OBRA | G9: =B43
F10: DESP. GERAIS | G10: =B58
A11: TOTAL: | B11: =B3-SUM(B5:B9) | F11: PROLABORE | G11: =B60
F12: LUCRO TOTAL: | G12: =G7-G8-G9-G10-G11
A14: CARTÃO DE CRÉDITO
A15: CARTÃO | B15: VALOR | C15: TAXA % | D15: DESCONTO | E15: VALOR LIQUIDO
A16: CRÉDITO | B16: 0 | C16: 3.09 | D16: =B16*C16/100 | E16: =B16-D16
A17: DÉBITO | B17: 0 | C17: 1.95 | D17: =B17*C17/100 | E17: =B17-D17
A18: CRÉDITO CARLOS | B18: 0 | C18: 2 | D18: =B18*C18/100 | E18: =B18-D18
A19: DÉBITO CARLOS | B19: 0 | C19: 2 | D19: =B19*C19/100 | E19: =B19-D19
A20: TOTAL EM CARTÃO | B20: =SUM(B16:B19) | D20: =SUM(D16:D19) | E20: =SUM(E16:E19)
A23: IFOOD
A24: CARTÃO | B24: VALOR | C24: TAXA % | D24: DESCONTO | E24: VALOR LIQUIDO ONLINE
A25: IFOOD - PAGO LOJA | C25: 12 | D25: =B25*C25/100
A26: IFOOD - PAGO ONLINE | C26: 15.5 | D26: =B26*C26/100 | E26: =B26-D27 | F26: VALOR PAGO ONLINE E COM TODOS OS DESCONTOS
A27: TOTAL EM IFOOD | B27: =SUM(B25:B26) | D27: =SUM(D25:D26) | E27: =SUM(E25:E26)
A30: DESPESAS NO DIA | C30: OBSERVAÇÕES
A31: CUSTO ALIMENTAR
A32: GENEROS ALIMENTICIOS
A33: GENEROS DESCARTAVEIS
A34: GENEROS DE LIMPEZA
A35: FRETES E CARRETOS
A36: HIGIENIZACAO - TIA DA LIMPEZA
A37: TOTAL - CUSTO ALIMENTAR | B37: =SUM(B32:B36)
A39: MÃO DE OBRA
A40: SALARIO DOS FUNCIONÁRIOS
A41: ALIMENTACAO
A42: VALE TRANSPORTE
A43: TOTAL - MÃO DE OBRA | B43: =SUM(B40:B42)
A45: DESPESAS OPERACIONAIS
A46: ÁGUA
A47: LUZ (ENERGIA)
...

Sheet 3º QUI
A1: PLANILHA DE CONTROLE DIÁRIO
A2: DINHEIRO | F2: DATA:
A3: TOTAL EM DINHEIRO: | G3: FAT. LIQUIDO
A4: DESPESAS PAGAS COM O DINHEIRO DO CAIXA | F4: DINHEIRO | G4: =B3
F5: CARTÃO | G5: =E20
F6: IFOOD | G6: =E27
F7: FAT. TOTAL: | G7: =G4+G5+G6
F8: DESP. ALIMENTAR | G8: =B37
F9: DESP. MÃO DE OBRA | G9: =B43
F10: DESP. GERAIS | G10: =B58
A11: TOTAL: | B11: =B3-SUM(B5:B10) | F11: PROLABORE | G11: =B60
F12: LUCRO TOTAL: | G12: =G7-G8-G9-G10-G11
A14: CARTÃO DE CRÉDITO
A15: CARTÃO | B15: VALOR | C15: TAXA % | D15: DESCONTO | E15: VALOR LIQUIDO
A16: CRÉDITO | B16: 0 | C16: 3.09 | D16: =B16*C16/100 | E16: =B16-D16
A17: DÉBITO | B17: 0 | C17: 1.95 | D17: =B17*C17/100 | E17: =B17-D17
A18: CRÉDITO CARLOS | B18: 0 | C18: 2 | D18: =B18*C18/100 | E18: =B18-D18
A19: DÉBITO CARLOS | B19: 0 | C19: 2 | D19: =B19*C19/100 | E19: =B19-D19
A20: TOTAL EM CARTÃO | B20: =SUM(B16:B19) | D20: =SUM(D16:D19) | E20: =SUM(E16:E19)
A23: IFOOD
A24: CARTÃO | B24: VALOR | C24: TAXA % | D24: DESCONTO | E24: VALOR LIQUIDO ONLINE
A25: IFOOD - PAGO LOJA | C25: 12 | D25: =B25*C25/100
A26: IFOOD - PAGO ONLINE | C26: 15.5 | D26: =B26*C26/100 | E26: =B26-D27 | F26: VALOR PAGO ONLINE E COM TODOS OS DESCONTOS
A27: TOTAL EM IFOOD | B27: =SUM(B25:B26) | D27: =SUM(D25:D26) | E27: =SUM(E25:E26)
A30: DESPESAS NO DIA | C30: OBSERVAÇÕES
A31: CUSTO ALIMENTAR
A32: GENEROS ALIMENTICIOS
A33: GENEROS DESCARTAVEIS
A34: GENEROS DE LIMPEZA
A35: FRETES E CARRETOS
A36: HIGIENIZACAO - TIA DA LIMPEZA
A37: TOTAL - CUSTO ALIMENTAR | B37: =SUM(B32:B36)
A39: MÃO DE OBRA
A40: SALARIO DOS FUNCIONÁRIOS
A41: ALIMENTACAO
A42: VALE TRANSPORTE
A43: TOTAL - MÃO DE OBRA | B43: =SUM(B40:B42)
A45: DESPESAS OPERACIONAIS
A46: ÁGUA
A47: LUZ (ENERGIA)
...

Sheet 3º SEX
A1: PLANILHA DE CONTROLE DIÁRIO
A2: DINHEIRO | F2: DATA:
A3: TOTAL EM DINHEIRO: | G3: FAT. LIQUIDO
A4: DESPESAS PAGAS COM O DINHEIRO DO CAIXA | F4: DINHEIRO | G4: =B3
F5: CARTÃO | G5: =E20
F6: IFOOD | G6: =E27
F7: FAT. TOTAL: | G7: =G4+G5+G6
F8: DESP. ALIMENTAR | G8: =B37
F9: DESP. MÃO DE OBRA | G9: =B43
F10: DESP. GERAIS | G10: =B58
A11: TOTAL: | B11: =B3-SUM(B5:B10) | F11: PROLABORE | G11: =B60
F12: LUCRO TOTAL: | G12: =G7-G8-G9-G10-G11
A14: CARTÃO DE CRÉDITO
A15: CARTÃO | B15: VALOR | C15: TAXA % | D15: DESCONTO | E15: VALOR LIQUIDO
A16: CRÉDITO | B16: 0 | C16: 3.09 | D16: =B16*C16/100 | E16: =B16-D16
A17: DÉBITO | B17: 0 | C17: 1.95 | D17: =B17*C17/100 | E17: =B17-D17
A18: CRÉDITO CARLOS | B18: 0 | C18: 2 | D18: =B18*C18/100 | E18: =B18-D18
A19: DÉBITO CARLOS | B19: 0 | C19: 2 | D19: =B19*C19/100 | E19: =B19-D19
A20: TOTAL EM CARTÃO | B20: =SUM(B16:B19) | D20: =SUM(D16:D19) | E20: =SUM(E16:E19)
A23: IFOOD
A24: CARTÃO | B24: VALOR | C24: TAXA % | D24: DESCONTO | E24: VALOR LIQUIDO ONLINE
A25: IFOOD - PAGO LOJA | C25: 12 | D25: =B25*C25/100
A26: IFOOD - PAGO ONLINE | C26: 15.5 | D26: =B26*C26/100 | E26: =B26-D27 | F26: VALOR PAGO ONLINE E COM TODOS OS DESCONTOS
A27: TOTAL EM IFOOD | B27: =SUM(B25:B26) | D27: =SUM(D25:D26) | E27: =SUM(E25:E26)
A30: DESPESAS NO DIA | C30: OBSERVAÇÕES
A31: CUSTO ALIMENTAR
A32: GENEROS ALIMENTICIOS
A33: GENEROS DESCARTAVEIS
A34: GENEROS DE LIMPEZA
A35: FRETES E CARRETOS
A36: HIGIENIZACAO - TIA DA LIMPEZA
A37: TOTAL - CUSTO ALIMENTAR | B37: =SUM(B32:B36)
A39: MÃO DE OBRA
A40: SALARIO DOS FUNCIONÁRIOS
A41: ALIMENTACAO
A42: VALE TRANSPORTE
A43: TOTAL - MÃO DE OBRA | B43: =SUM(B40:B42)
A45: DESPESAS OPERACIONAIS
A46: ÁGUA
A47: LUZ (ENERGIA)
...

Sheet 4º SEG
A1: PLANILHA DE CONTROLE DIÁRIO
A2: DINHEIRO | F2: DATA:
A3: TOTAL EM DINHEIRO: | G3: FAT. LIQUIDO
A4: DESPESAS PAGAS COM O DINHEIRO DO CAIXA | F4: DINHEIRO | G4: =B3
F5: CARTÃO | G5: =E20
F6: IFOOD | G6: =E27
F7: FAT. TOTAL: | G7: =G4+G5+G6
F8: DESP. ALIMENTAR | G8: =B37
F9: DESP. MÃO DE OBRA | G9: =B43
F10: DESP. GERAIS | G10: =B58
A11: TOTAL: | B11: =B3-SUM(B5:B9) | F11: PROLABORE | G11: =B60
F12: LUCRO TOTAL: | G12: =G7-G8-G9-G10-G11
A14: CARTÃO DE CRÉDITO
A15: CARTÃO | B15: VALOR | C15: TAXA % | D15: DESCONTO | E15: VALOR LIQUIDO
A16: CRÉDITO | B16: 0 | C16: 3.09 | D16: =B16*C16/100 | E16: =B16-D16
A17: DÉBITO | B17: 0 | C17: 1.95 | D17: =B17*C17/100 | E17: =B17-D17
A18: CRÉDITO CARLOS | B18: 0 | C18: 2 | D18: =B18*C18/100 | E18: =B18-D18
A19: DÉBITO CARLOS | B19: 0 | C19: 2 | D19: =B19*C19/100 | E19: =B19-D19
A20: TOTAL EM CARTÃO | B20: =SUM(B16:B19) | D20: =SUM(D16:D19) | E20: =SUM(E16:E19)
A23: IFOOD
A24: CARTÃO | B24: VALOR | C24: TAXA % | D24: DESCONTO | E24: VALOR LIQUIDO ONLINE
A25: IFOOD - PAGO LOJA | C25: 12 | D25: =B25*C25/100
A26: IFOOD - PAGO ONLINE | C26: 15.5 | D26: =B26*C26/100 | E26: =B26-D27 | F26: VALOR PAGO ONLINE E COM TODOS OS DESCONTOS
A27: TOTAL EM IFOOD | B27: =SUM(B25:B26) | D27: =SUM(D25:D26) | E27: =SUM(E25:E26)
A30: DESPESAS NO DIA | C30: OBSERVAÇÕES
A31: CUSTO ALIMENTAR
A32: GENEROS ALIMENTICIOS
A33: GENEROS DESCARTAVEIS
A34: GENEROS DE LIMPEZA
A35: FRETES E CARRETOS
A36: HIGIENIZACAO - TIA DA LIMPEZA
A37: TOTAL - CUSTO ALIMENTAR | B37: =SUM(B32:B36)
A39: MÃO DE OBRA
A40: SALARIO DOS FUNCIONÁRIOS | B40: 0
A41: ALIMENTACAO
A42: VALE TRANSPORTE | B42: 0
A43: TOTAL - MÃO DE OBRA | B43: =SUM(B40:B42)
A45: DESPESAS OPERACIONAIS
A46: ÁGUA | B46: 0
A47: LUZ (ENERGIA) | B47: 0
...

Sheet 4º TER
A1: PLANILHA DE CONTROLE DIÁRIO
A2: DINHEIRO | F2: DATA:
A3: TOTAL EM DINHEIRO: | G3: FAT. LIQUIDO
A4: DESPESAS PAGAS COM O DINHEIRO DO CAIXA | F4: DINHEIRO | G4: =B3
F5: CARTÃO | G5: =E20
F6: IFOOD | G6: =E27
F7: FAT. TOTAL: | G7: =G4+G5+G6
F8: DESP. ALIMENTAR | G8: =B37
F9: DESP. MÃO DE OBRA | G9: =B43
F10: DESP. GERAIS | G10: =B58
A11: TOTAL: | B11: =B3-SUM(B5:B9) | F11: PROLABORE | G11: =B60
F12: LUCRO TOTAL: | G12: =G7-G8-G9-G10-G11
A14: CARTÃO DE CRÉDITO
A15: CARTÃO | B15: VALOR | C15: TAXA % | D15: DESCONTO | E15: VALOR LIQUIDO
A16: CRÉDITO | B16: 0 | C16: 3.09 | D16: =B16*C16/100 | E16: =B16-D16
A17: DÉBITO | B17: 0 | C17: 1.95 | D17: =B17*C17/100 | E17: =B17-D17
A18: CRÉDITO CARLOS | B18: 0 | C18: 2 | D18: =B18*C18/100 | E18: =B18-D18
A19: DÉBITO CARLOS | B19: 0 | C19: 2 | D19: =B19*C19/100 | E19: =B19-D19
A20: TOTAL EM CARTÃO | B20: =SUM(B16:B19) | D20: =SUM(D16:D19) | E20: =SUM(E16:E19)
A23: IFOOD
A24: CARTÃO | B24: VALOR | C24: TAXA % | D24: DESCONTO | E24: VALOR LIQUIDO ONLINE
A25: IFOOD - PAGO LOJA | C25: 12 | D25: =B25*C25/100
A26: IFOOD - PAGO ONLINE | C26: 15.5 | D26: =B26*C26/100 | E26: =B26-D27 | F26: VALOR PAGO ONLINE E COM TODOS OS DESCONTOS
A27: TOTAL EM IFOOD | B27: =SUM(B25:B26) | D27: =SUM(D25:D26) | E27: =SUM(E25:E26)
A30: DESPESAS NO DIA | C30: OBSERVAÇÕES
A31: CUSTO ALIMENTAR
A32: GENEROS ALIMENTICIOS
A33: GENEROS DESCARTAVEIS
A34: GENEROS DE LIMPEZA
A35: FRETES E CARRETOS
A36: HIGIENIZACAO - TIA DA LIMPEZA
A37: TOTAL - CUSTO ALIMENTAR | B37: =SUM(B32:B36)
A39: MÃO DE OBRA
A40: SALARIO DOS FUNCIONÁRIOS | B40: 0
A41: ALIMENTACAO | B41: 0
A42: VALE TRANSPORTE | B42: 0
A43: TOTAL - MÃO DE OBRA | B43: =SUM(B40:B42)
A45: DESPESAS OPERACIONAIS
A46: ÁGUA | B46: 0
A47: LUZ (ENERGIA) | B47: 0
...

Sheet 4º QUA
A1: PLANILHA DE CONTROLE DIÁRIO
A2: DINHEIRO | F2: DATA:
A3: TOTAL EM DINHEIRO: | G3: FAT. LIQUIDO
A4: DESPESAS PAGAS COM O DINHEIRO DO CAIXA | F4: DINHEIRO | G4: =B3
F5: CARTÃO | G5: =E20
F6: IFOOD | G6: =E27
F7: FAT. TOTAL: | G7: =G4+G5+G6
F8: DESP. ALIMENTAR | G8: =B37
F9: DESP. MÃO DE OBRA | G9: =B43
F10: DESP. GERAIS | G10: =B58
A11: TOTAL: | B11: =B3-SUM(B5:B9) | F11: PROLABORE | G11: =B60
F12: LUCRO TOTAL: | G12: =G7-G8-G9-G10-G11
A14: CARTÃO DE CRÉDITO
A15: CARTÃO | B15: VALOR | C15: TAXA % | D15: DESCONTO | E15: VALOR LIQUIDO
A16: CRÉDITO | C16: 3.09 | D16: =B16*C16/100 | E16: =B16-D16
A17: DÉBITO | C17: 1.95 | D17: =B17*C17/100 | E17: =B17-D17
A18: CRÉDITO CARLOS | C18: 2 | D18: =B18*C18/100 | E18: =B18-D18
A19: DÉBITO CARLOS | C19: 2 | D19: =B19*C19/100 | E19: =B19-D19
A20: TOTAL EM CARTÃO | B20: =SUM(B16:B19) | D20: =SUM(D16:D19) | E20: =SUM(E16:E19)
A23: IFOOD
A24: CARTÃO | B24: VALOR | C24: TAXA % | D24: DESCONTO | E24: VALOR LIQUIDO ONLINE
A25: IFOOD - PAGO LOJA | C25: 12 | D25: =B25*C25/100
A26: IFOOD - PAGO ONLINE | C26: 15.5 | D26: =B26*C26/100 | E26: =B26-D27 | F26: VALOR PAGO ONLINE E COM TODOS OS DESCONTOS
A27: TOTAL EM IFOOD | B27: =SUM(B25:B26) | D27: =SUM(D25:D26) | E27: =SUM(E25:E26)
A30: DESPESAS NO DIA | C30: OBSERVAÇÕES
A31: CUSTO ALIMENTAR
A32: GENEROS ALIMENTICIOS
A33: GENEROS DESCARTAVEIS
A34: GENEROS DE LIMPEZA
A35: FRETES E CARRETOS
A36: HIGIENIZACAO - TIA DA LIMPEZA
A37: TOTAL - CUSTO ALIMENTAR | B37: =SUM(B32:B36)
A39: MÃO DE OBRA
A40: SALARIO DOS FUNCIONÁRIOS | B40: 0
A41: ALIMENTACAO | B41: 0
A42: VALE TRANSPORTE | B42: 0
A43: TOTAL - MÃO DE OBRA | B43: =SUM(B40:B42)
A45: DESPESAS OPERACIONAIS
A46: ÁGUA | B46: 0
A47: LUZ (ENERGIA) | B47: 0
...

Sheet 4º QUI
A1: PLANILHA DE CONTROLE DIÁRIO
A2: DINHEIRO | F2: DATA:
A3: TOTAL EM DINHEIRO: | G3: FAT. LIQUIDO
A4: DESPESAS PAGAS COM O DINHEIRO DO CAIXA | F4: DINHEIRO | G4: =B3
F5: CARTÃO | G5: =E20
F6: IFOOD | G6: =E27
F7: FAT. TOTAL: | G7: =G4+G5+G6
F8: DESP. ALIMENTAR | G8: =B37
F9: DESP. MÃO DE OBRA | G9: =B43
F10: DESP. GERAIS | G10: =B58
A11: TOTAL: | B11: =B3-SUM(B5:B9) | F11: PROLABORE | G11: =B60
F12: LUCRO TOTAL: | G12: =G7-G8-G9-G10-G11
A14: CARTÃO DE CRÉDITO
A15: CARTÃO | B15: VALOR | C15: TAXA % | D15: DESCONTO | E15: VALOR LIQUIDO
A16: CRÉDITO À VISTA | C16: 4.99 | D16: =B16*C16/100 | E16: =B16-D16
A17: DÉBITO | C17: 2.6 | D17: =B17*C17/100 | E17: =B17-D17
A18: CRÉDITO 2X | C18: 9.49 | D18: =B18*C18/100 | E18: =B18-D18
A19: CRÉDITO 3X | C19: 11.49 | D19: =B19*C19/100 | E19: =B19-D19
A20: TOTAL EM CARTÃO | B20: =SUM(B16:B19) | D20: =SUM(D16:D19) | E20: =SUM(E16:E19)
A23: IFOOD
A24: CARTÃO | B24: VALOR | C24: TAXA % | D24: DESCONTO | E24: VALOR LIQUIDO ONLINE
A25: IFOOD - PAGO LOJA | C25: 12 | D25: =B25*C25/100
A26: IFOOD - PAGO ONLINE | C26: 15.5 | D26: =B26*C26/100 | E26: =B26-D27 | F26: VALOR PAGO ONLINE E COM TODOS OS DESCONTOS
A27: TOTAL EM IFOOD | B27: =SUM(B25:B26) | D27: =SUM(D25:D26) | E27: =SUM(E25:E26)
A30: DESPESAS NO DIA | C30: OBSERVAÇÕES
A31: CUSTO ALIMENTAR
A32: GENEROS ALIMENTICIOS
A33: GENEROS DESCARTAVEIS
A34: GENEROS DE LIMPEZA
A35: FRETES E CARRETOS
A36: HIGIENIZACAO - TIA DA LIMPEZA
A37: TOTAL - CUSTO ALIMENTAR | B37: =SUM(B32:B36)
A39: MÃO DE OBRA
A40: SALARIO DOS FUNCIONÁRIOS
A41: ALIMENTACAO
A42: VALE TRANSPORTE
A43: TOTAL - MÃO DE OBRA | B43: =SUM(B40:B42)
A45: DESPESAS OPERACIONAIS
A46: ÁGUA
A47: LUZ (ENERGIA)
...

Sheet 4º SEX
A1: PLANILHA DE CONTROLE DIÁRIO
A2: DINHEIRO | F2: DATA:
A3: TOTAL EM DINHEIRO: | G3: FAT. LIQUIDO
A4: DESPESAS PAGAS COM O DINHEIRO DO CAIXA | F4: DINHEIRO | G4: =B3
F5: CARTÃO | G5: =E20
F6: IFOOD | G6: =E27
F7: FAT. TOTAL: | G7: =G4+G5+G6
F8: DESP. ALIMENTAR | G8: =B37
F9: DESP. MÃO DE OBRA | G9: =B43
F10: DESP. GERAIS | G10: =B58
A11: TOTAL: | B11: =B3-SUM(B5:B9) | F11: PROLABORE | G11: =B60
F12: LUCRO TOTAL: | G12: =G7-G8-G9-G10-G11
A14: CARTÃO DE CRÉDITO
A15: CARTÃO | B15: VALOR | C15: TAXA % | D15: DESCONTO | E15: VALOR LIQUIDO
A16: CRÉDITO | C16: 3.09 | D16: =B16*C16/100 | E16: =B16-D16
A17: DÉBITO | C17: 1.95 | D17: =B17*C17/100 | E17: =B17-D17
A18: CRÉDITO CARLOS | C18: 2 | D18: =B18*C18/100 | E18: =B18-D18
A19: DÉBITO CARLOS | C19: 2 | D19: =B19*C19/100 | E19: =B19-D19
A20: TOTAL EM CARTÃO | B20: =SUM(B16:B19) | D20: =SUM(D16:D19) | E20: =SUM(E16:E19)
A23: IFOOD
A24: CARTÃO | B24: VALOR | C24: TAXA % | D24: DESCONTO | E24: VALOR LIQUIDO ONLINE
A25: IFOOD - PAGO LOJA | C25: 12 | D25: =B25*C25/100
A26: IFOOD - PAGO ONLINE | C26: 15.5 | D26: =B26*C26/100 | E26: =B26-D27
A27: TOTAL EM IFOOD | B27: =SUM(B25:B26) | D27: =SUM(D25:D26) | E27: =SUM(E25:E26)
A30: DESPESAS NO DIA | C30: OBSERVAÇÕES
A31: CUSTO ALIMENTAR
A32: GENEROS ALIMENTICIOS
A33: GENEROS DESCARTAVEIS
A34: GENEROS DE LIMPEZA
A35: FRETES E CARRETOS
A36: HIGIENIZACAO - TIA DA LIMPEZA
A37: TOTAL - CUSTO ALIMENTAR | B37: =SUM(B32:B36)
A39: MÃO DE OBRA
A40: SALARIO DOS FUNCIONÁRIOS | B40: 0
A41: ALIMENTACAO
A42: VALE TRANSPORTE | B42: 0
A43: TOTAL - MÃO DE OBRA | B43: =SUM(B40:B42)
A45: DESPESAS OPERACIONAIS
A46: ÁGUA | B46: 0
A47: LUZ (ENERGIA) | B47: 0
...

Sheet 5º SEG
A1: PLANILHA DE CONTROLE DIÁRIO
A2: DINHEIRO | F2: DATA: | G2: 45684
A3: TOTAL EM DINHEIRO: | G3: FAT. LIQUIDO
A4: DESPESAS PAGAS COM O DINHEIRO DO CAIXA | F4: DINHEIRO | G4: =B3
F5: CARTÃO | G5: =E20
F6: IFOOD | G6: =E27
F7: FAT. TOTAL: | G7: =G4+G5+G6
F8: DESP. ALIMENTAR | G8: =B37
F9: DESP. MÃO DE OBRA | G9: =B43
F10: DESP. GERAIS | G10: =B58
A11: TOTAL: | B11: =B3-SUM(B5:B9) | F11: PROLABORE | G11: =B60
F12: LUCRO TOTAL: | G12: =G7-G8-G9-G10-G11
A14: CARTÃO DE CRÉDITO
A15: CARTÃO | B15: VALOR | C15: TAXA % | D15: DESCONTO | E15: VALOR LIQUIDO
A16: CRÉDITO | C16: 3.09 | D16: =B16*C16/100 | E16: =B16-D16
A17: DÉBITO | C17: 1.95 | D17: =B17*C17/100 | E17: =B17-D17
A18: CRÉDITO CARLOS | C18: 2 | D18: =B18*C18/100 | E18: =B18-D18
A19: DÉBITO CARLOS | C19: 2 | D19: =B19*C19/100 | E19: =B19-D19
A20: TOTAL EM CARTÃO | B20: =SUM(B16:B19) | D20: =SUM(D16:D19) | E20: =SUM(E16:E19)
A23: IFOOD
A24: CARTÃO | B24: VALOR | C24: TAXA % | D24: DESCONTO | E24: VALOR LIQUIDO ONLINE
A25: IFOOD - PAGO LOJA | C25: 12 | D25: =B25*C25/100
A26: IFOOD - PAGO ONLINE | C26: 15.5 | D26: =B26*C26/100 | E26: =B26-D27
A27: TOTAL EM IFOOD | B27: =SUM(B25:B26) | D27: =SUM(D25:D26) | E27: =SUM(E25:E26)
A30: DESPESAS NO DIA | C30: OBSERVAÇÕES
A31: CUSTO ALIMENTAR
A32: GENEROS ALIMENTICIOS | B32: 0
A33: GENEROS DESCARTAVEIS | B33: 0
A34: GENEROS DE LIMPEZA | B34: 0
A35: FRETES E CARRETOS | B35: 0
A36: HIGIENIZACAO - TIA DA LIMPEZA | B36: 0
A37: TOTAL - CUSTO ALIMENTAR | B37: =SUM(B32:B36)
A39: MÃO DE OBRA
A40: SALARIO DOS FUNCIONÁRIOS | B40: 0
A41: ALIMENTACAO | B41: 0
A42: VALE TRANSPORTE | B42: 0
A43: TOTAL - MÃO DE OBRA | B43: =SUM(B40:B42)
A45: DESPESAS OPERACIONAIS
A46: ÁGUA | B46: 0
A47: LUZ (ENERGIA) | B47: 0
...

Sheet 5º TER
A1: PLANILHA DE CONTROLE DIÁRIO
A2: DINHEIRO | F2: DATA:
A3: TOTAL EM DINHEIRO: | G3: FAT. LIQUIDO
A4: DESPESAS PAGAS COM O DINHEIRO DO CAIXA | F4: DINHEIRO | G4: =B3
F5: CARTÃO | G5: =E20
F6: IFOOD | G6: =E27
F7: FAT. TOTAL: | G7: =G4+G5+G6
F8: DESP. ALIMENTAR | G8: =B37
F9: DESP. MÃO DE OBRA | G9: =B43
F10: DESP. GERAIS | G10: =B58
A11: TOTAL: | B11: =B3-SUM(B5:B9) | F11: PROLABORE | G11: =B60
F12: LUCRO TOTAL: | G12: =G7-G8-G9-G10-G11
A14: CARTÃO DE CRÉDITO
A15: CARTÃO | B15: VALOR | C15: TAXA % | D15: DESCONTO | E15: VALOR LIQUIDO
A16: CRÉDITO | C16: 3.09 | D16: =B16*C16/100 | E16: =B16-D16
A17: DÉBITO | C17: 1.95 | D17: =B17*C17/100 | E17: =B17-D17
A18: CRÉDITO CARLOS | C18: 2 | D18: =B18*C18/100 | E18: =B18-D18
A19: DÉBITO CARLOS | C19: 2 | D19: =B19*C19/100 | E19: =B19-D19
A20: TOTAL EM CARTÃO | B20: =SUM(B16:B19) | D20: =SUM(D16:D19) | E20: =SUM(E16:E19)
A23: IFOOD
A24: CARTÃO | B24: VALOR | C24: TAXA % | D24: DESCONTO | E24: VALOR LIQUIDO ONLINE
A25: IFOOD - PAGO LOJA | C25: 12 | D25: =B25*C25/100
A26: IFOOD - PAGO ONLINE | C26: 15.5 | D26: =B26*C26/100 | E26: =B26-D27 | F26: VALOR PAGO ONLINE E COM TODOS OS DESCONTOS
A27: TOTAL EM IFOOD | B27: =SUM(B25:B26) | D27: =SUM(D25:D26) | E27: =SUM(E25:E26)
A30: DESPESAS NO DIA | C30: OBSERVAÇÕES
A31: CUSTO ALIMENTAR
A32: GENEROS ALIMENTICIOS | B32: 0
A33: GENEROS DESCARTAVEIS | B33: 0
A34: GENEROS DE LIMPEZA | B34: 0
A35: FRETES E CARRETOS | B35: 0
A36: HIGIENIZACAO - TIA DA LIMPEZA | B36: 0
A37: TOTAL - CUSTO ALIMENTAR | B37: =SUM(B32:B36)
A39: MÃO DE OBRA
A40: SALARIO DOS FUNCIONÁRIOS | B40: 0
A41: ALIMENTACAO | B41: 0
A42: VALE TRANSPORTE | B42: 0
A43: TOTAL - MÃO DE OBRA | B43: =SUM(B40:B42)
A45: DESPESAS OPERACIONAIS
A46: ÁGUA | B46: 0
A47: LUZ (ENERGIA) | B47: 0
...

Sheet 5º QUA
A1: PLANILHA DE CONTROLE DIÁRIO
A2: DINHEIRO | F2: DATA:
A3: TOTAL EM DINHEIRO: | G3: FAT. LIQUIDO
A4: DESPESAS PAGAS COM O DINHEIRO DO CAIXA | F4: DINHEIRO | G4: =B3
F5: CARTÃO | G5: =E20
F6: IFOOD | G6: =E27
F7: FAT. TOTAL: | G7: =G4+G5+G6
F8: DESP. ALIMENTAR | G8: =B37
F9: DESP. MÃO DE OBRA | G9: =B43
F10: DESP. GERAIS | G10: =B58
A11: TOTAL: | B11: =B3-SUM(B5:B9) | F11: PROLABORE | G11: =B60
F12: LUCRO TOTAL: | G12: =G7-G8-G9-G10-G11
A14: CARTÃO DE CRÉDITO
A15: CARTÃO | B15: VALOR | C15: TAXA % | D15: DESCONTO | E15: VALOR LIQUIDO
A16: CRÉDITO | C16: 3.09 | D16: =B16*C16/100 | E16: =B16-D16
A17: DÉBITO | C17: 1.95 | D17: =B17*C17/100 | E17: =B17-D17
A18: CRÉDITO CARLOS | C18: 2 | D18: =B18*C18/100 | E18: =B18-D18
A19: DÉBITO CARLOS | C19: 2 | D19: =B19*C19/100 | E19: =B19-D19
A20: TOTAL EM CARTÃO | B20: =SUM(B16:B19) | D20: =SUM(D16:D19) | E20: =SUM(E16:E19)
A23: IFOOD
A24: CARTÃO | B24: VALOR | C24: TAXA % | D24: DESCONTO | E24: VALOR LIQUIDO ONLINE
A25: IFOOD - PAGO LOJA | C25: 12 | D25: =B25*C25/100
A26: IFOOD - PAGO ONLINE | C26: 15.5 | D26: =B26*C26/100 | E26: =B26-D27 | F26: VALOR PAGO ONLINE E COM TODOS OS DESCONTOS
A27: TOTAL EM IFOOD | B27: =SUM(B25:B26) | D27: =SUM(D25:D26) | E27: =SUM(E25:E26)
A30: DESPESAS NO DIA | C30: OBSERVAÇÕES
A31: CUSTO ALIMENTAR
A32: GENEROS ALIMENTICIOS | B32: 0
A33: GENEROS DESCARTAVEIS | B33: 0
A34: GENEROS DE LIMPEZA | B34: 0
A35: FRETES E CARRETOS | B35: 0
A36: HIGIENIZACAO - TIA DA LIMPEZA | B36: 0
A37: TOTAL - CUSTO ALIMENTAR | B37: =SUM(B32:B36)
A39: MÃO DE OBRA
A40: SALARIO DOS FUNCIONÁRIOS | B40: 0
A41: ALIMENTACAO | B41: 0
A42: VALE TRANSPORTE | B42: 0
A43: TOTAL - MÃO DE OBRA | B43: =SUM(B40:B42)
A45: DESPESAS OPERACIONAIS
A46: ÁGUA | B46: 0
A47: LUZ (ENERGIA) | B47: 0
...

Sheet 5º QUI
A1: PLANILHA DE CONTROLE DIÁRIO
A2: DINHEIRO | F2: DATA:
A3: TOTAL EM DINHEIRO: | G3: FAT. LIQUIDO
A4: DESPESAS PAGAS COM O DINHEIRO DO CAIXA | F4: DINHEIRO | G4: =B3
F5: CARTÃO | G5: =E20
F6: IFOOD | G6: =E27
F7: FAT. TOTAL: | G7: =G4+G5+G6
F8: DESP. ALIMENTAR | G8: =B37
F9: DESP. MÃO DE OBRA | G9: =B43
F10: DESP. GERAIS | G10: =B58
A11: TOTAL: | B11: =B3-SUM(B5:B10) | F11: PROLABORE | G11: =B60
F12: LUCRO TOTAL: | G12: =G7-G8-G9-G10-G11
A14: CARTÃO DE CRÉDITO
A15: CARTÃO | B15: VALOR | C15: TAXA % | D15: DESCONTO | E15: VALOR LIQUIDO
A16: CRÉDITO | C16: 3.09 | D16: =B16*C16/100 | E16: =B16-D16
A17: DÉBITO | C17: 1.95 | D17: =B17*C17/100 | E17: =B17-D17
A18: CRÉDITO CARLOS | C18: 2 | D18: =B18*C18/100 | E18: =B18-D18
A19: DÉBITO CARLOS | C19: 2 | D19: =B19*C19/100 | E19: =B19-D19
A20: TOTAL EM CARTÃO | B20: =SUM(B16:B19) | D20: =SUM(D16:D19) | E20: =SUM(E16:E19)
A23: IFOOD
A24: CARTÃO | B24: VALOR | C24: TAXA % | D24: DESCONTO | E24: VALOR LIQUIDO ONLINE
A25: IFOOD - PAGO LOJA | C25: 12 | D25: =B25*C25/100
A26: IFOOD - PAGO ONLINE | C26: 15.5 | D26: =B26*C26/100 | E26: =B26-D27
A27: TOTAL EM IFOOD | B27: =SUM(B25:B26) | D27: =SUM(D25:D26) | E27: =SUM(E25:E26)
A30: DESPESAS NO DIA | C30: OBSERVAÇÕES
A31: CUSTO ALIMENTAR
A32: GENEROS ALIMENTICIOS
A33: GENEROS DESCARTAVEIS
A34: GENEROS DE LIMPEZA
A35: FRETES E CARRETOS
A36: HIGIENIZACAO - TIA DA LIMPEZA
A37: TOTAL - CUSTO ALIMENTAR | B37: =SUM(B32:B36)
A39: MÃO DE OBRA
A40: SALARIO DOS FUNCIONÁRIOS
A41: ALIMENTACAO
A42: VALE TRANSPORTE | B42: 0
A43: TOTAL - MÃO DE OBRA | B43: =SUM(B40:B42)
A45: DESPESAS OPERACIONAIS
A46: ÁGUA | B46: 0
A47: LUZ (ENERGIA) | B47: 0
...

Sheet 5º SEX
A1: PLANILHA DE CONTROLE DIÁRIO
A2: DINHEIRO | F2: DATA:
A3: TOTAL EM DINHEIRO: | G3: FAT. LIQUIDO
A4: DESPESAS PAGAS COM O DINHEIRO DO CAIXA | F4: DINHEIRO | G4: =B3
F5: CARTÃO | G5: =E20
F6: IFOOD | G6: =E27
F7: FAT. TOTAL: | G7: =G4+G5+G6
F8: DESP. ALIMENTAR | G8: =B37
F9: DESP. MÃO DE OBRA | G9: =B43
F10: DESP. GERAIS | G10: =B58
A11: TOTAL: | B11: =B3-SUM(B5:B10) | F11: PROLABORE | G11: =B60
F12: LUCRO TOTAL: | G12: =G7-G8-G9-G10-G11
A14: CARTÃO DE CRÉDITO
A15: CARTÃO | B15: VALOR | C15: TAXA % | D15: DESCONTO | E15: VALOR LIQUIDO
A16: CRÉDITO | C16: 3.09 | D16: =B16*C16/100 | E16: =B16-D16
A17: DÉBITO | C17: 1.95 | D17: =B17*C17/100 | E17: =B17-D17
A18: CRÉDITO CARLOS | C18: 2 | D18: =B18*C18/100 | E18: =B18-D18
A19: DÉBITO CARLOS | C19: 2 | D19: =B19*C19/100 | E19: =B19-D19
A20: TOTAL EM CARTÃO | B20: =SUM(B16:B19) | D20: =SUM(D16:D19) | E20: =SUM(E16:E19)
A23: IFOOD
A24: CARTÃO | B24: VALOR | C24: TAXA % | D24: DESCONTO | E24: VALOR LIQUIDO ONLINE
A25: IFOOD - PAGO LOJA | C25: 12 | D25: =B25*C25/100
A26: IFOOD - PAGO ONLINE | C26: 15.5 | D26: =B26*C26/100 | E26: =B26-D27 | F26: VALOR PAGO ONLINE E COM TODOS OS DESCONTOS
A27: TOTAL EM IFOOD | B27: =SUM(B25:B26) | D27: =SUM(D25:D26) | E27: =SUM(E25:E26)
A30: DESPESAS NO DIA | C30: OBSERVAÇÕES
A31: CUSTO ALIMENTAR
A32: GENEROS ALIMENTICIOS
A33: GENEROS DESCARTAVEIS
A34: GENEROS DE LIMPEZA
A35: FRETES E CARRETOS
A36: HIGIENIZACAO - TIA DA LIMPEZA
A37: TOTAL - CUSTO ALIMENTAR | B37: =SUM(B32:B36)
A39: MÃO DE OBRA
A40: SALARIO DOS FUNCIONÁRIOS | B40: 0
A41: ALIMENTACAO
A42: VALE TRANSPORTE | B42: 0
A43: TOTAL - MÃO DE OBRA | B43: =SUM(B40:B42)
A45: DESPESAS OPERACIONAIS
A46: ÁGUA | B46: 0
A47: LUZ (ENERGIA) | B47: 0
...

Sheet RESUMO GERAL
A1: RESUMO DE CONTROLE DIÁRIO | G1: RESUMO
A2: DINHEIRO | G2: TOTAL FAT. BRUTO | H2: =B3+B11
A3: TOTAL EM DINHEIRO: | B3: ='1º SEX'!B3+'1ª QUA'!B3+'1ª TER'!B3+'2º SEX'!B3+'2º SEG'!B3+'2º TER'!B3+'3º SEX'!B3+'3º SEG'!B3+'3º TER'!B3+'4º SEX'!B3+'4º SEG'!B3+'4º TER'!B3+'5º SEX'!B3+'5º SEG'!B3+'5º TER'!B3+'1º QUI'!B3+'2º QUI'!B3+'3º QUI'!B3+'4º QUI'!B3+'5º QUI'!B3+'1ª SEG'!B3+'2º QUA'!B3+'3º QUA'!B3+'4º TER'!B3+'5º QUA'!B3 | G3: DINHEIRO | H3: =B3
G4: CARTÃO E PLANOS | H4: =E11
A5: CARTÃO E PLANOS | G5: TOTAL FAT. LIQUIDO | H5: =H3+H4
A6: CARTÃO | B6: VALOR BRUTO | C6: TAXA % | D6: DESCONTO | E6: VALOR LIQUIDO | G6: DESP. ALIMENTAR | H6: =B22
A7: CARTÃO | B7: ='1º SEX'!B16+'1ª QUA'!B16+'1ª TER'!B16+'2º SEX'!B16+'2º SEG'!B16+'2º TER'!B16+'3º SEX'!B16+'3º SEG'!B16+'3º TER'!B16+'4º SEX'!B16+'4º SEG'!B16+'4º TER'!B16+'5º SEX'!B16+'5º SEG'!B16+'5º TER'!B16+'1º QUI'!B16+'2º QUI'!B16+'3º QUI'!B16+'4º QUI'!B16+'5º QUI'!B16+'1ª SEG'!B16+'2º QUA'!B16+'4º QUA'!B16+'5º QUA'!B16+'3º QUA'!B16 | D7: =B7*C7/100 | E7: =B7-D7 | G7: DESP. MÃO DE OBRA | H7: =B28
A8: PLANOS | B8: ='1º SEX'!B17+'1ª QUA'!B17+'1ª TER'!B17+'2º SEX'!B17+'2º SEG'!B17+'2º TER'!B17+'3º SEX'!B17+'3º SEG'!B17+'3º TER'!B17+'4º SEX'!B17+'4º SEG'!B17+'4º TER'!B17+'5º SEX'!B17+'5º SEG'!B17+'5º TER'!B17+'1º QUI'!B17+'2º QUI'!B17+'3º QUI'!B17+'4º QUI'!B17+'5º QUI'!B17+'1ª SEG'!B17+'2º QUA'!B17+'3º QUA'!B17+'4º QUA'!B17+'5º QUA'!B17 | D8: =B8*C8/100 | E8: =B8-D8 | G8: DESP. OPERACIONAIS | H8: =B42
A9: CRÉDITO 2X | B9: ='1º SEX'!B18+'1ª QUA'!B18+'1ª TER'!B18+'2º SEX'!B18+'2º SEG'!B18+'2º TER'!B18+'3º SEX'!B18+'3º SEG'!B18+'3º TER'!B18+'4º SEX'!B18+'4º SEG'!B18+'4º TER'!B18+'5º SEX'!B18+'5º SEG'!B18+'5º TER'!B18+'1º QUI'!B18+'2º QUI'!B18+'3º QUI'!B18+'4º QUI'!B18+'5º QUI'!B18+'1ª SEG'!B18+'2º QUA'!B18+'3º QUA'!B18+'4º QUA'!B18+'5º QUA'!B18 | D9: =B9*C9/100 | E9: ='1º SEX'!E18+'1ª QUA'!E18+'1ª TER'!E18+'2º SEX'!E18+'2º SEG'!E18+'2º TER'!E18+'3º SEX'!E18+'3º SEG'!E18+'3º TER'!E18+'4º SEX'!E18+'4º SEG'!E18+'4º TER'!E18+'5º SEX'!E18+'5º SEG'!E18+'5º TER'!E18+'1º QUI'!E18+'2º QUI'!E18+'3º QUI'!E18+'4º QUI'!E18+'5º QUI'!E18 | G9: PROLABORE | H9: =B44
A10: CRÉDITO 3X | B10: ='1º QUI'!B19+'1º SEX'!B19+'1ª QUA'!B19+'1ª TER'!B19+'2º QUI'!B19+'2º SEX'!B19+'2º SEG'!B19+'2º TER'!B19+'3º QUI'!B19+'3º SEX'!B19+'3º SEG'!B19+'3º TER'!B19+'4º QUI'!B19+'4º SEX'!B19+'4º SEG'!B19+'4º TER'!B19+'5º QUI'!B19+'5º SEX'!B19+'5º SEG'!B19+'5º TER'!B19+'1ª SEG'!B19+'2º QUA'!B19+'3º QUA'!B19+'4º QUA'!B19+'5º QUA'!B19 | D10: =B10*C10/100 | E10: ='1º SEX'!E19+'1ª QUA'!E19+'1ª TER'!E19+'2º SEX'!E19+'2º SEG'!E19+'2º TER'!E19+'3º SEX'!E19+'3º SEG'!E19+'3º TER'!E19+'4º SEX'!E19+'4º SEG'!E19+'4º TER'!E19+'5º SEX'!E19+'5º SEG'!E19+'5º TER'!E19+'1º QUI'!E19+'2º QUI'!E19+'3º QUI'!E19+'4º QUI'!E19+'5º QUI'!E19 | G10: LUCRO TOTAL: | H10: =H5-H6-H7-H8-H9
A11: TOTAL EM CARTÃO | B11: =SUM(B7:B10) | D11: =SUM(D7:D10) | E11: =SUM(E7:E10)
G12: DESPESAS TOTAIS | H12: =SUM(H6:H8)
A15: DESPESAS NO DIA | C15: % | D15: Percentual em cima do Faturamento Bruto
A16: CUSTO ALIMENTAR
A17: GENEROS ALIMENTICIOS | B17: ='1º SEX'!B32+'1ª QUA'!B32+'1ª TER'!B32+'2º SEX'!B32+'2º SEG'!B32+'2º TER'!B32+'3º SEX'!B32+'3º SEG'!B32+'3º TER'!B32+'4º SEX'!B32+'4º SEG'!B32+'4º TER'!B32+'5º SEX'!B32+'5º SEG'!B32+'5º TER'!B32+'1º QUI'!B32+'2º QUI'!B32+'3º QUI'!B32+'4º QUI'!B32+'5º QUI'!B32+'1ª SEG'!B32+'2º QUA'!B32+'3º QUA'!B32+'4º QUA'!B32+'5º QUA'!B32
A18: GENEROS DESCARTAVEIS | B18: ='1º SEX'!B33+'1ª QUA'!B33+'1ª TER'!B33+'2º SEX'!B33+'2º SEG'!B33+'2º TER'!B33+'3º SEX'!B33+'3º SEG'!B33+'3º TER'!B33+'4º SEX'!B33+'4º SEG'!B33+'4º TER'!B33+'5º SEX'!B33+'5º SEG'!B33+'5º TER'!B33+'1º QUI'!B33+'2º QUI'!B33+'3º QUI'!B33+'4º QUI'!B33+'5º QUI'!B33+'1ª SEG'!B33+'2º QUA'!B33+'3º QUA'!B33+'4º QUA'!B33+'5º QUA'!B33
A19: GENEROS DE LIMPEZA | B19: ='1º SEX'!B34+'1ª QUA'!B34+'1ª TER'!B34+'2º SEX'!B34+'2º SEG'!B34+'2º TER'!B34+'3º SEX'!B34+'3º SEG'!B34+'3º TER'!B34+'4º SEX'!B34+'4º SEG'!B34+'4º TER'!B34+'5º SEX'!B34+'5º SEG'!B34+'5º TER'!B34+'1º QUI'!B34+'2º QUI'!B34+'3º QUI'!B34+'4º QUI'!B34+'5º QUI'!B34+'1ª SEG'!B34+'2º QUA'!B34+'3º QUA'!B34+'4º QUA'!B34+'5º QUA'!B34
A20: FRETES E CARRETOS | B20: ='1º SEX'!B35+'1ª QUA'!B35+'1ª TER'!B35+'2º SEX'!B35+'2º SEG'!B35+'2º TER'!B35+'3º SEX'!B35+'3º SEG'!B35+'3º TER'!B35+'4º SEX'!B35+'4º SEG'!B35+'4º TER'!B35+'5º SEX'!B35+'5º SEG'!B35+'5º TER'!B35+'1º QUI'!B35+'2º QUI'!B35+'3º QUI'!B35+'4º QUI'!B35+'5º QUI'!B35+'1ª SEG'!B35+'2º QUA'!B35+'3º QUA'!B35+'4º QUA'!B35+'5º QUA'!B35
A21: HIGIENIZACAO - TIA DA LIMPEZA | B21: ='1º SEX'!B36+'1ª QUA'!B36+'1ª TER'!B36+'2º SEX'!B36+'2º SEG'!B36+'2º TER'!B36+'3º SEX'!B36+'3º SEG'!B36+'3º TER'!B36+'4º SEX'!B36+'4º SEG'!B36+'4º TER'!B36+'5º SEX'!B36+'5º SEG'!B36+'5º TER'!B36+'1º QUI'!B36+'2º QUI'!B36+'3º QUI'!B36+'4º QUI'!B36+'5º QUI'!B36+'1ª SEG'!B36+'2º QUA'!B36+'3º QUA'!B36+'4º QUA'!B36+'5º QUA'!B36
A22: TOTAL - CUSTO ALIMENTAR | B22: =SUM(B17:B21) | C22: =(B22/H2)
A24: MÃO DE OBRA
A25: SALARIO DOS FUNCIONÁRIOS | B25: ='1º SEX'!B40+'1ª QUA'!B40+'1ª TER'!B40+'2º SEX'!B40+'2º SEG'!B40+'2º TER'!B40+'3º SEX'!B40+'3º SEG'!B40+'3º TER'!B40+'4º SEX'!B40+'4º SEG'!B40+'4º TER'!B40+'5º SEX'!B40+'5º SEG'!B40+'5º TER'!B40+'1º QUI'!B40+'2º QUI'!B40+'3º QUI'!B40+'4º QUI'!B40+'5º QUI'!B40+'1ª SEG'!B40+'2º QUA'!B40+'3º QUA'!B40+'4º QUA'!B40+'5º QUA'!B40
A26: ALIMENTACAO | B26: ='1º SEX'!B41+'1ª QUA'!B41+'1ª TER'!B41+'2º SEX'!B41+'2º SEG'!B41+'2º TER'!B41+'3º SEX'!B41+'3º SEG'!B41+'3º TER'!B41+'4º SEX'!B41+'4º SEG'!B41+'4º TER'!B41+'5º SEX'!B41+'5º SEG'!B41+'5º TER'!B41+'1º QUI'!B41+'2º QUI'!B41+'3º QUI'!B41+'4º QUI'!B41+'5º QUI'!B41+'1ª SEG'!B41+'2º QUA'!B41+'3º QUA'!B41+'4º QUA'!B41+'5º QUA'!B41
A27: VALE TRANSPORTE | B27: ='1º SEX'!B42+'1ª QUA'!B42+'1ª TER'!B42+'2º SEX'!B42+'2º SEG'!B42+'2º TER'!B42+'3º SEX'!B42+'3º SEG'!B42+'3º TER'!B42+'4º SEX'!B42+'4º SEG'!B42+'4º TER'!B42+'5º SEX'!B42+'5º SEG'!B42+'5º TER'!B42+'1º QUI'!B42+'2º QUI'!B42+'3º QUI'!B42+'4º QUI'!B42+'5º QUI'!B42+'1ª SEG'!B42+'2º QUA'!B42+'3º QUA'!B42+'4º QUA'!B42+'5º QUA'!B42
A28: TOTAL - MÃO DE OBRA | B28: =SUM(B25:B27) | C28: =(B28/H2)
A30: DESPESAS OPERACIONAIS
A31: ÁGUA | B31: ='1º SEX'!B46+'1ª QUA'!B46+'1ª TER'!B46+'2º SEX'!B46+'2º SEG'!B46+'2º TER'!B46+'3º SEX'!B46+'3º SEG'!B46+'3º TER'!B46+'4º SEX'!B46+'4º SEG'!B46+'4º TER'!B46+'5º SEX'!B46+'5º SEG'!B46+'5º TER'!B46+'1º QUI'!B46+'2º QUI'!B46+'3º QUI'!B46+'4º QUI'!B46+'5º QUI'!B46+'1ª SEG'!B46+'2º QUA'!B46+'3º QUA'!B46+'4º QUA'!B46+'5º QUA'!B46
A32: LUZ (ENERGIA) | B32: ='1º SEX'!B47+'1ª QUA'!B47+'1ª TER'!B47+'2º SEX'!B47+'2º SEG'!B47+'2º TER'!B47+'3º SEX'!B47+'3º SEG'!B47+'3º TER'!B47+'4º SEX'!B47+'4º SEG'!B47+'4º TER'!B47+'5º SEX'!B47+'5º SEG'!B47+'5º TER'!B47+'1º QUI'!B47+'2º QUI'!B47+'3º QUI'!B47+'4º QUI'!B47+'5º QUI'!B47+'1ª SEG'!B47+'2º QUA'!B47+'3º QUA'!B47+'4º QUA'!B47+'5º QUA'!B47
A33: MANUTENCOES E REPAROS | B33: ='1º SEX'!B49+'1ª QUA'!B49+'1ª TER'!B49+'2º SEX'!B49+'2º SEG'!B49+'2º TER'!B49+'3º SEX'!B49+'3º SEG'!B49+'3º TER'!B49+'4º SEX'!B49+'4º SEG'!B49+'4º TER'!B49+'5º SEX'!B49+'5º SEG'!B49+'5º TER'!B49+'1º QUI'!B49+'2º QUI'!B49+'3º QUI'!B49+'4º QUI'!B49+'5º QUI'!B49+'1ª SEG'!B49+'2º QUA'!B49+'3º QUA'!B49+'4º QUA'!B49+'5º QUA'!B49
A34: INTERNET | B34: ='1º SEX'!B50+'1ª QUA'!B50+'1ª TER'!B50+'2º SEX'!B50+'2º SEG'!B50+'2º TER'!B50+'3º SEX'!B50+'3º SEG'!B50+'3º TER'!B50+'4º SEX'!B50+'4º SEG'!B50+'4º TER'!B50+'5º SEX'!B50+'5º SEG'!B50+'5º TER'!B50+'1º QUI'!B50+'2º QUI'!B50+'3º QUI'!B50+'4º QUI'!B50+'5º QUI'!B50+'1ª SEG'!B50+'2º QUA'!B50+'3º QUA'!B50+'4º QUA'!B50+'5º QUA'!B50
A35: TELEFONE / FAX | B35: ='1º SEX'!B51+'1ª QUA'!B51+'1ª TER'!B51+'2º SEX'!B51+'2º SEG'!B51+'2º TER'!B51+'3º SEX'!B51+'3º SEG'!B51+'3º TER'!B51+'4º SEX'!B51+'4º SEG'!B51+'4º TER'!B51+'5º SEX'!B51+'5º SEG'!B51+'5º TER'!B51+'1º QUI'!B51+'2º QUI'!B51+'3º QUI'!B51+'4º QUI'!B51+'5º QUI'!B51+'1ª SEG'!B51+'2º QUA'!B51+'3º QUA'!B51+'4º QUA'!B51+'5º QUA'!B51
A36: UNIFORMES | B36: ='1º SEX'!B52+'1ª QUA'!B52+'1ª TER'!B52+'2º SEX'!B52+'2º SEG'!B52+'2º TER'!B52+'3º SEX'!B52+'3º SEG'!B52+'3º TER'!B52+'4º SEX'!B52+'4º SEG'!B52+'4º TER'!B52+'5º SEX'!B52+'5º SEG'!B52+'5º TER'!B52+'1º QUI'!B52+'2º QUI'!B52+'3º QUI'!B52+'4º QUI'!B52+'5º QUI'!B52+'1ª SEG'!B52+'2º QUA'!B52+'3º QUA'!B52+'4º QUA'!B52+'5º QUA'!B52
A37: UTENSILIOS | B37: ='1º SEX'!B53+'1ª QUA'!B53+'1ª TER'!B53+'2º SEX'!B53+'2º SEG'!B53+'2º TER'!B53+'3º SEX'!B53+'3º SEG'!B53+'3º TER'!B53+'4º SEX'!B53+'4º SEG'!B53+'4º TER'!B53+'5º SEX'!B53+'5º SEG'!B53+'5º TER'!B53+'1º QUI'!B53+'2º QUI'!B53+'3º QUI'!B53+'4º QUI'!B53+'5º QUI'!B53+'1ª SEG'!B53+'2º QUA'!B53+'3º QUA'!B53+'4º QUA'!B53+'5º QUA'!B53
A38: EPI - PROTECAO INDIVIDUAL | B38: ='1º SEX'!B54+'1ª QUA'!B54+'1ª TER'!B54+'2º SEX'!B54+'2º SEG'!B54+'2º TER'!B54+'3º SEX'!B54+'3º SEG'!B54+'3º TER'!B54+'4º SEX'!B54+'4º SEG'!B54+'4º TER'!B54+'5º SEX'!B54+'5º SEG'!B54+'5º TER'!B54+'1º QUI'!B54+'2º QUI'!B54+'3º QUI'!B54+'4º QUI'!B54+'5º QUI'!B54+'1ª SEG'!B54+'2º QUA'!B54+'3º QUA'!B54+'4º QUA'!B54+'5º QUA'!B54
A39: OUTROS CUSTOS GERAIS | B39: ='1º SEX'!B55+'1ª QUA'!B55+'1ª TER'!B55+'2º SEX'!B55+'2º SEG'!B55+'2º TER'!B55+'3º SEX'!B55+'3º SEG'!B55+'3º TER'!B55+'4º SEX'!B55+'4º SEG'!B55+'4º TER'!B55+'5º SEX'!B55+'5º SEG'!B55+'5º TER'!B55+'1º QUI'!B55+'2º QUI'!B55+'3º QUI'!B55+'4º QUI'!B55+'5º QUI'!B55+'1ª SEG'!B55+'2º QUA'!B55+'3º QUA'!B55+'4º QUA'!B55+'5º QUA'!B55
A40: REEMBOLSO DE LOCOMOCAO | B40: ='1º SEX'!B56+'1ª QUA'!B56+'1ª TER'!B56+'2º SEX'!B56+'2º SEG'!B56+'2º TER'!B56+'3º SEX'!B56+'3º SEG'!B56+'3º TER'!B56+'4º SEX'!B56+'4º SEG'!B56+'4º TER'!B56+'5º SEX'!B56+'5º SEG'!B56+'5º TER'!B56+'1º QUI'!B56+'2º QUI'!B56+'3º QUI'!B56+'4º QUI'!B56+'5º QUI'!B56+'1ª SEG'!B56+'2º QUA'!B56+'3º QUA'!B56+'4º QUA'!B56+'5º QUA'!B56
A41: COPIAS E IMPRESSOES | B41: ='1º SEX'!B57+'1ª QUA'!B57+'1ª TER'!B57+'2º SEX'!B57+'2º SEG'!B57+'2º TER'!B57+'3º SEX'!B57+'3º SEG'!B57+'3º TER'!B57+'4º SEX'!B57+'4º SEG'!B57+'4º TER'!B57+'5º SEX'!B57+'5º SEG'!B57+'5º TER'!B57+'1º QUI'!B57+'2º QUI'!B57+'3º QUI'!B57+'4º QUI'!B57+'5º QUI'!B57+'1ª SEG'!B57+'2º QUA'!B57+'3º QUA'!B57+'4º QUA'!B57+'5º QUA'!B57
A42: TOTAL - DESPESAS OPERACIONAIS | B42: =SUM(B31:B41) | C42: =(B42/H2)
A44: PROLABORE | B44: ='1º SEX'!B60+'1ª QUA'!B60+'1ª TER'!B60+'2º SEX'!B60+'2º SEG'!B60+'2º TER'!B60+'3º SEX'!B60+'3º SEG'!B60+'3º TER'!B60+'4º SEX'!B60+'4º SEG'!B60+'4º TER'!B60+'5º SEX'!B60+'5º SEG'!B60+'5º TER'!B60+'1º QUI'!B60+'2º QUI'!B60+'3º QUI'!B60+'4º QUI'!B60+'5º QUI'!B60+'1ª SEG'!B60+'2º QUA'!B60+'3º QUA'!B60+'4º QUA'!B60+'5º QUA'!B60 | C44: =(B44/H2)
A46: LUCRO TOTAL | B46: =H5-B22-B28-B42-B44 | C46: =(B46/H2)

Sheet RESUMO DESPESAS
A1: ALIMENTICIOS | B1: DESCARTAVEIS | C1: LIMPEZA | D1: FRETES | E1: FAXINEIRA | F1: SALARIOS | G1: ALIMENT. PESSOAL | H1: VALE TRANSPORTE | I1: AGUA | J1: LUZ | K1: MANUTENCOES | L1: INTERNET | M1: TELEFONE | N1: UNIFORMES | O1: UTENSILIOS | P1: EPI | Q1: OUTROS CUSTOS GERAIS | R1: REEMBOLSO DE LOC. | S1: IMPRESSOES | T1: PROLABORE | U1: MES
A2: 0 | B2: 0 | C2: 0 | D2: 0 | E2: 180 | F2: 962.36 | G2: 0 | H2: 277.2 | I2: 0 | J2: 0 | K2: 0 | L2: 0 | M2: 0 | N2: 0 | O2: 0 | P2: 0 | Q2: 8350.35 | R2: 0 | S2: 0 | T2: 0 | U2: Janeiro

Sheet RESUMO RECEITAS
A1: FATURAMENTO | B1: DINHEIRO | C1: CARTAO E PLANOS | D1: MES
A2: 9471.87 | B2: 3540 | C2: 5931.87 | D2: Janeiro
